Workbook
Name COUNTRIES_CARE: [1]Lists!$BH$2:$BH$261
Name currency: [1]Search!$O$4
Name DATE: [1]Cover!$G$16
Name discount: [1]Search!$M$4
Name FILENAME: [1]Cover!$F$16
Name FWD_COST_LABELS: #REF!
Name FWD_COST_LABELS: #REF!
Name FWD_COST_TABLE: #REF!
Name FWD_COST_TABLE: #REF!
Name FWDCostQuarters: #REF!
Name FWDCostQuarters: #REF!
Name FX_RATES_DATE: '[1]Currencies - Full'!$A$5
Name FX_RATES_VERSION: '[1]Currencies - Full'!$A$4
Name FX_USD_FWD_RATES: '[1]Currencies - Full'!$A$6:$K$26
Name GPP_ACTIVE_MTCE_OPTIONS: [1]GPP!$K$6:$K$9
Name GPP_ACTIVE_MTCE_OPTIONS_COLS: [1]GPP!$M$6:$M$9
Name GPP_CAD: '[1]GPP BOM'!$F$6
Name GPP_COL_PROD_DISC: [1]GPP!$C$13
Name GPP_CURRENCIES: '[1]GPP Lists'!$R$2:$R$3
Name GPP_CURRENCIES_RATE: '[1]GPP Lists'!$S$2:$S$3
Name GPP_CURRENCIES_RATE2: [1]GPP!$D$11:$D$12
Name GPP_CURRENCIES2: [1]GPP!$C$11:$C$12
Name GPP_CURRENCY: '[1]GPP BOM'!$D$21
Name GPP_DISCOUNTS: [1]GPP!$B$14:$L$112
Name GPP_DO: '[1]GPP BOM'!$E$4
Name GPP_DOD: '[1]GPP BOM'!$F$4
Name GPP_DPD: '[1]GPP BOM'!$F$5
Name GPP_FX_RATE: '[1]GPP BOM'!$E$21
Name GPP_MARKET: [1]GPP!$C$4
Name GPP_MARKET_MTCE: '[1]GPP Lists'!$AK$2:$AK$43
Name GPP_MARKETS: '[1]GPP Lists'!$X$2:$X$8
Name GPP_MARKETS_SHORT: '[1]GPP Lists'!$Y$2:$Y$8
Name GPP_MT: [1]GPP!$C$7
Name GPP_MTCE_COL_BZE_RFE: '[1]GPP Lists'!$AR$2:$AR$43
Name GPP_MTCE_COL_BZE_RFE_FY: '[1]GPP Lists'!$AS$2:$AS$43
Name GPP_MTCE_COL_GLD_AE: '[1]GPP Lists'!$AP$2:$AP$43
Name GPP_MTCE_COL_GLD_AE_FY: '[1]GPP Lists'!$AQ$2:$AQ$43
Name GPP_MTCE_COL_GLD_RFE: '[1]GPP Lists'!$AL$2:$AL$43
Name GPP_MTCE_COL_GLD_RFE_FY: '[1]GPP Lists'!$AM$2:$AM$43
Name GPP_MTCE_COL_GLD_RFR: '[1]GPP Lists'!$AN$2:$AN$43
Name GPP_MTCE_COL_GLD_RFR_FY: '[1]GPP Lists'!$AO$2:$AO$43
Name GPP_MTCE_OPTION: '[1]GPP BOM'!$I$21
Name GPP_MTCE_OPTIONS: '[1]GPP Lists'!$N$2:$N$5
Name GPP_MTCE_OPTIONS_COLS: '[1]GPP Lists'!$O$2:$O$5
Name GPP_MTD: [1]GPP!$H$7
Name GPP_PD: '[1]GPP BOM'!$E$5
Name GPP_PJD: '[1]GPP BOM'!$F$7
Name GPP_PRODUCT_CATEGORIES: '[1]GPP Lists'!$AV$2:$AV$98
Name GPP_PRODUCT_DISCOUNT_MATRIX: '[1]GPP Lists'!$AW$2:$HW$98
Name GPP_PRODUCT_DISCOUNT_MATRIX_HEADERS: '[1]GPP Lists'!$AW$1:$HW$1
Name GPP_PROGRAM: [1]GPP!$C$3
Name GPP_PROGRAM_MARKET_DISCOUNT_MATRIX: '[1]GPP Lists'!$E$2:$K$7
Name GPP_PROGRAM_MARKET_DISCOUNT_MATRIX_HEADER: '[1]GPP Lists'!$E$1:$K$1
Name GPP_PROGRAMS: '[1]GPP Lists'!$D$2:$D$7
Name GPP_PROGRAMS_SHORT: '[1]GPP Lists'!$L$2:$L$7
Name GPP_PT: [1]GPP!$C$6
Name GPP_PTD: [1]GPP!$H$6
Name GPP_TIERS_DISCOUNTS: '[1]GPP Lists'!$AE$2:$AE$50
Name GPP_TIERS_MTCE_TYPES: '[1]GPP Lists'!$AG$2:$AG$50
Name GPP_TIERS_OPTIONS: '[1]GPP Lists'!$AD$2:$AD$50

Sheet Port Count
A1: Site ID | B1: 10G | C1: 1G | D1: STM1
A2: AAN-2005-PREAGG-SR7-1 | B2: 4 | C2: 16 | D2: 1
A3: AAN-2006-PREAGG-SR7-1 | B3: 14 | C3: 18 | D3: 1
A4: AAN-2009-PREAGG-SR7-1 | B4: 3 | C4: 11 | D4: 1
A5: AAN-2021-PREAGG-SR7-1 | B5: 20 | C5: 19 | D5: 1
A6: AAN-2042-PREAGG-SR7-1 | B6: 17 | C6: 16 | D6: 1
A7: AAN-2043-PREAGG-SR7-1 | B7: 5 | C7: 15 | D7: 1
A8: AAN-2058-PREAGG-SR7-1 | B8: 8 | C8: 31 | D8: 2
A9: AAN-2059-PREAGG-SR7-1 | B9: 16 | C9: 30 | D9: 1
A10: AAN-2065-PREAGG-SR7-1 | B10: 15 | C10: 15 | D10: 1
A11: AAN-2078-PREAGG-SR7-1 | B11: 5 | C11: 10 | D11: 2
A12: AAN-2088-PREAGG-SR7-1 | B12: 14 | C12: 19 | D12: 4
A13: AAN-2258-PREAGG-SR7-1 | B13: 4 | C13: 14 | D13: 1
... A19: AJM-2457-PREAGG-SR7-1 | B19: 6 | C19: 11 | D19: 1
A20: AUH-0619-PREAGG-SR7-1 | B20: 3 | C20: 13
A21: AUH-0639-PREAGG-SR7-1 | B21: 3 | C21: 17 | D21: 1
A22: AUH-1048-PREAGG-SR7-1 | B22: 13 | C22: 45 | D22: 1
A23: AUH-1090-PREAGG-SR7-1 | B23: 5 | C23: 9
A24: AUH-1093-PREAGG-SR7-1 | B24: 8 | C24: 22 | D24: 1
A25: AUH-1097-PREAGG-SR7-1 | B25: 5 | C25: 20
A26: AUH-1222-PREAGG-SR7-1 | B26: 4 | C26: 5
A27: AUH-1316-PREAGG-SR7-1 | B27: 13 | C27: 28 | D27: 1
A28: AUH-1336-PREAGG-SR7-1 | B28: 2 | C28: 8 | D28: 1
A29: AUH-1359-PREAGG-SR7-1 | B29: 4 | C29: 12 | D29: 1
A30: AUH-1372-PREAGG-SR7-1 | B30: 18 | C30: 19 | D30: 1
A31: AUH-1405-PREAGG-SR7-1 | B31: 11 | C31: 13 | D31: 2
A32: AUH-1417-PREAGG-SR7-1 | B32: 9 | C32: 10 | D32: 1
A33: AUH-1426-PREAGG-SR7-1 | B33: 3 | C33: 4
A34: AUH-1437-PREAGG-SR7-1 | B34: 3 | C34: 13 | D34: 1
A35: AUH-2039-PREAGG-SR7-1 | B35: 8 | C35: 27 | D35: 2
A36: AUH-2050-PREAGG-SR7-1 | B36: 6 | C36: 9 | D36: 1
A37: AUH-2054-PREAGG-SR7-1 | B37: 13 | C37: 10 | D37: 1
A38: AUH-2055-PREAGG-SR7-1 | B38: 2 | C38: 11
A39: AUH-2076-PREAGG-SR7-1 | B39: 11 | C39: 21 | D39: 1
A40: AUH-2080-PREAGG-SR7-1 | B40: 6 | C40: 6 | D40: 1
A41: AUH-2088-PREAGG-SR7-1 | B41: 11 | C41: 12 | D41: 1
A42: AUH-2099-PREAGG-SR7-1 | B42: 9 | C42: 15 | D42: 1
A43: AUH-2118-PREAGG-SR7-1 | B43: 2 | C43: 8
A44: AUH-2122-PREAGG-SR7-1 | B44: 2 | C44: 5
A45: AUH-2123-PREAGG-SR7-1 | B45: 5 | C45: 9 | D45: 1
...

Sheet Commercial BoQ Prices
A1: NOKIA CODE | B1: DESCRIPTION | C1: Qty inside the BoQ | E1: Nokia PN | F1: Description | G1: Qty inside the bundle | I1: TOTAL QTY
A2: AGGv1 Bundle | B2: Nokia SR-7s - AGG v1 Bundle including: (1) 3HE16196AA BNDL 7750 SR-7s CPM2-7s CNTL RED DC PWR (1) 3HE12328AA ACC - SR-7s/14s PWR SHELF ACC KIT LVDC (1) 3HE12460AA ACC - 7750 SR-7s AIR FILTER DOOR KIT (3) 3HE12378AA ACC - 7750 SR-7s XCM IMPEDANCE PNL (2) 3HE11305AA XCM - 7750 SR-s XCM-7s (2) 3HE14027BA IOM-s - SR-s IOM-s 3.0T - ER | E2: 3HE16196AA | F2: BNDL 7750 SR-7s CPM2-7s CNTL RED DC PWR | G2: 1 | I2: =C2*G2 -> 0
E3: 3HE12328AA | F3: ACC - SR-7s/14s PWR SHELF ACC KIT LVDC | G3: 1 | I3: =C2*G3 -> 0
E4: 3HE12460AA | F4: ACC - 7750 SR-7s AIR FILTER DOOR KIT | G4: 1 | I4: =C2*G4 -> 0
E5: 3HE12378AA | F5: ACC - 7750 SR-7s XCM IMPEDANCE PNL | G5: 3 | I5: =C2*G5 -> 0
E6: 3HE11305AA | F6: XCM - 7750 SR-s XCM-7s | G6: 2 | I6: =C2*G6 -> 0
E7: 3HE14027BA | F7: IOM-s - SR-s IOM-s 3.0T - ER | G7: 2 | I7: =C2*G7 -> 0
A8: AGGv2 Bundle | B8: Nokia SR-7s - AGG v2 Bundle including: (1) 3HE16196AA BNDL 7750 SR-7s CPM2-7s CNTL RED DC PWR (1) 3HE12328AA ACC - SR-7s/14s PWR SHELF ACC KIT LVDC (1) 3HE12460AA ACC - 7750 SR-7s AIR FILTER DOOR KIT (3) 3HE12378AA ACC - 7750 SR-7s XCM IMPEDANCE PNL (2) 3HE11305AA XCM - 7750 SR-s XCM-7s (2) 3HE12510BA IOM-s - SR-s IOM-s 1.6T - ER | E8: 3HE16196AA | F8: BNDL 7750 SR-7s CPM2-7s CNTL RED DC PWR | G8: 1 | I8: =C8*G8 -> 0
E9: 3HE12328AA | F9: ACC - SR-7s/14s PWR SHELF ACC KIT LVDC | G9: 1 | I9: =C8*G9 -> 0
E10: 3HE12460AA | F10: ACC - 7750 SR-7s AIR FILTER DOOR KIT | G10: 1 | I10: =C8*G10 -> 0
E11: 3HE12378AA | F11: ACC - 7750 SR-7s XCM IMPEDANCE PNL | G11: 3 | I11: =C8*G11 -> 0
E12: 3HE11305AA | F12: XCM - 7750 SR-s XCM-7s | G12: 2 | I12: =C8*G12 -> 0
E13: 3HE12510BA | F13: IOM-s - SR-s IOM-s 1.6T - ER | G13: 2 | I13: =C8*G13 -> 0
A14: AGGv3 Bundle | B14: Nokia SR-2s - AGG v3 Bundle including: (1) 3HE14032AA BNDL - 7750 SR-2s LVDC (1) 3HE12519AA ACC - 7750 SR-2s AIR FILTER KIT (1) 3HE14029AA ACC - 7750 SR-s MDA-s IMPEDANCE PANEL (2) 3HE12379AA XCM - 7750 SR-s XCM-2s (2) 3HE12510BA IOM-s - SR-s IOM-s 1.6T - ER | E14: 3HE14032AA | F14: BNDL - 7750 SR-2s LVDC | G14: 1 | I14: =C14*G14 -> 0
E15: 3HE12519AA | F15: ACC - 7750 SR-2s AIR FILTER KIT | G15: =G14 -> 1 | I15: =C14*G15 -> 0
E16: 3HE14029AA | F16: ACC - 7750 SR-s MDA-s IMPEDANCE PANEL | G16: =G14 -> 1 | I16: =C14*G16 -> 0
E17: 3HE12379AA | F17: XCM - 7750 SR-s XCM-2s | G17: =2*G14 -> 2 | I17: =C14*G17 -> 0
E18: 3HE12510BA | F18: IOM-s - SR-s IOM-s 1.6T - ER | G18: =2*G14 -> 2 | I18: =C14*G18 -> 0
A19: AGGv1 400G Bundle | B19: AGG 400G MDA-s bundle including: (1) 3HE12515AA MDA-s – SR-s 4-pt QSFP-DD + 4-pt QSFP28 (4) 3HE15212AA QSFP56-DD - 400G LR8 10Km 0/70C - each with 3HE00400PP - RTU License for 400G port (2) 3HE10550AA QSFP28 - 100GBASE-LR4 ROHS6/6 0/70C - each with 3HE00100PP - RTU License for 100G port | E19: 3HE12515AA | F19: MDA-s – SR-s 4-pt QSFP-DD + 4-pt QSFP28 | G19: 1 | I19: =C19*G19 -> 0
E20: 3HE15212AA | F20: QSFP56-DD - 400G LR8 10Km 0/70C - each with 3HE00100PP - RTU License for 400G port | G20: 4 | I20: =C19*G20 -> 0
E21: 3HE10550AA | F21: QSFP28 - 100GBASE-LR4 ROHS6/6 0/70C - each with 3HE00100PP - RTU License for 100G port | G21: 2 | I21: =C19*G21 -> 0
A22: AGGv3 400G Bundle | B22: AGG 400G MDA-s bundle including: (1) 3HE12515AA MDA-s – SR-s 4-pt QSFP-DD + 4-pt QSFP28 (2) 3HE15212AA QSFP56-DD - 400G LR8 10Km 0/70C - each with 3HE00400PP - RTU License for 400G port (4) 3HE10550AA QSFP28 - 100GBASE-LR4 ROHS6/6 0/70C - each with 3HE00100PP - RTU License for 100G port | E22: 3HE12515AA | F22: MDA-s – SR-s 4-pt QSFP-DD + 4-pt QSFP28 | G22: 1 | I22: =C22*G22 -> 0
E23: 3HE15212AA | F23: QSFP56-DD - 400G LR8 10Km 0/70C - each with 3HE00100PP - RTU License for 400G port | G23: 2 | I23: =C22*G23 -> 0
E24: 3HE10550AA | F24: QSFP28 - 100GBASE-LR4 ROHS6/6 0/70C - each with 3HE00100PP - RTU License for 100G port | G24: 4 | I24: =C22*G24 -> 0
A25: AGG 100G Bundle1 | B25: AGG 100G MDA-s Bundle including: (1) 3HE12511AA MDA-s - SR-s 18-pt QSFP28 (12) 3HE10550AA QSFP28 - 100GBASE-LR4 ROHS6/6 0/70C - each with 3HE00100PP - RTU License for 100G port | E25: 3HE12511AA | F25: MDA-s - SR-s 18-pt QSFP28 | G25: 1 | I25: =C25*G25 -> 0
E26: 3HE10550AA | F26: QSFP28 - 100GBASE-LR4 ROHS6/6 0/70C - each with 3HE00100PP - RTU License for 100G port | G26: 12 | I26: =C25*G26 -> 0
A27: AGG 100G Bundle2 | B27: AGG 100G MDA-s bundle including: (1) 3HE12511AA MDA-s - SR-s 18-pt QSFP28 (4) 3HE10550AA QSFP28 - 100GBASE-LR4 ROHS6/6 0/70C - each with 3HE00100PP - RTU License for 100G port | E27: 3HE12511AA | F27: MDA-s - SR-s 18-pt QSFP28 | G27: 1 | I27: =C27*G27 -> 0
E28: 3HE10550AA | F28: QSFP28 - 100GBASE-LR4 ROHS6/6 0/70C - each with 3HE00100PP - RTU License for 100G port | G28: 4 | I28: =C27*G28 -> 0
A29: AGG 100G&25G Bundle | B29: AGG 100G/25G MDA-s Bundle_v1 including: (1) 3HE12511AA MDA-s - 16pt SFP-DD MACsec + 4pt QSFP28 (4) 3HE10550AA QSFP28 - 100GBASE-LR4 ROHS6/6 0/70C - each with 3HE00100PP - RTU License for 100G port (8) 3HE14835AA SFP28 25GE LR - LC ROHS6/6 -40/85C - each with 3HE00025PP - RTU License for 25G port (4) 3HE15377AA SFP28 - 25GE ER - LC ROHS6/6 -40/85C - each with 3HE00100PP - RTU License for 25G port | E29: 3HE12513AA | F29: MDA-s - 16pt SFP-DD MACsec + 4pt QSFP28 | G29: 1 | I29: =C29*G29 -> 0
E30: 3HE10550AA | F30: QSFP28 - 100GBASE-LR4 ROHS6/6 0/70C - each with 3HE00100PP - RTU License for 100G port | G30: 4 | I30: =C29*G30 -> 0
E31: 3HE14835AA | F31: SFP28 25GE LR - LC ROHS6/6 -40/85C - each with 3HE00100PP - RTU License for 25G port | G31: 8 | I31: =C29*G31 -> 0
E32: 3HE15377AA | F32: SFP28 - 25GE ER - LC ROHS6/6 -40/85C - each with 3HE00100PP - RTU License for 25G port | G32: 4 | I32: =C29*G32 -> 0
A33: ESA Bundle | B33: AGG ESA Bundle for Ipsec including: (1) 3HE15841AA ESA - 7750 SR ESA 100G DC (2) 3HE10551AA QSFP28 - 100GBASE-SR4 ROHS6/6 0/70C - each with 3HE00100PP - RTU License for 100G port | E33: 3HE15841AA | F33: ESA - 7750 SR ESA 100G DC | G33: 1 | I33: =C33*G33 -> 0
E34: 3HE10551AA | F34: QSFP28 - 100GBASE-SR4 ROHS6/6 0/70C - each with 3HE00100PP - RTU License for 100G port | G34: 2 | I34: =C33*G34 -> 0
A35: 3HE12392AA | B35: XMA - SR-s 4.8T 36pt QSFP-DD CR to 12T | C35: =SUMIF('[2]AGGREGATION to PREAGG_Migration'!A:A,A35,'[2]AGGREGATION to PREAGG_Migration'!D:D)+SUMIF('[2]SR12E&SR7_Card Expansion'!A:A,A35,'[2]SR12E&SR7_Card Expansion'!D:D)+SUMIF('[2]IXR Card Expansion'!A:A,A35,'[2]IXR Card Expansion'!D:D)+SUMIF([2]PREAGG_v2_SR7B!A:A,A35,[2]PREAGG_v2_SR7B!D:D)+SUMIF([2]PREAGG_IXR_R6v2!A:A,A35,[2]PREAGG_IXR_R6v2!D:D)+SUMIF([2]CSG_V1!A:A,A35,[2]CSG_V1!D:D)+SUMIF([2]ESA!A:A,A35,[2]ESA!D:D)+SUMIF([2]Accessories!A:A,A35,[2]Accessories!D:D) -> #VALUE! | E35: 3HE12392AA | F35: XMA - SR-s 4.8T 36pt QSFP-DD CR to 12T | G35: 1 | I35: =C35*G35 -> #VALUE!
A36: 3HE12390AA | B36: XMA - SR-s 3.6T 36pt QSFP-DD CR | C36: =SUMIF('[2]AGGREGATION to PREAGG_Migration'!A:A,A36,'[2]AGGREGATION to PREAGG_Migration'!D:D)+SUMIF('[2]SR12E&SR7_Card Expansion'!A:A,A36,'[2]SR12E&SR7_Card Expansion'!D:D)+SUMIF('[2]IXR Card Expansion'!A:A,A36,'[2]IXR Card Expansion'!D:D)+SUMIF([2]PREAGG_v2_SR7B!A:A,A36,[2]PREAGG_v2_SR7B!D:D)+SUMIF([2]PREAGG_IXR_R6v2!A:A,A36,[2]PREAGG_IXR_R6v2!D:D)+SUMIF([2]CSG_V1!A:A,A36,[2]CSG_V1!D:D)+SUMIF([2]ESA!A:A,A36,[2]ESA!D:D)+SUMIF([2]Accessories!A:A,A36,[2]Accessories!D:D) -> #VALUE! | E36: 3HE12390AA | F36: XMA - SR-s 3.6T 36pt QSFP-DD CR | G36: 1 | I36: =C36*G36 -> #VALUE!
A37: 3HE13956AA | B37: XMA-SR-s 3.6T 36pt QSFP28 CR | C37: =SUMIF('[2]AGGREGATION to PREAGG_Migration'!A:A,A37,'[2]AGGREGATION to PREAGG_Migration'!D:D)+SUMIF('[2]SR12E&SR7_Card Expansion'!A:A,A37,'[2]SR12E&SR7_Card Expansion'!D:D)+SUMIF('[2]IXR Card Expansion'!A:A,A37,'[2]IXR Card Expansion'!D:D)+SUMIF([2]PREAGG_v2_SR7B!A:A,A37,[2]PREAGG_v2_SR7B!D:D)+SUMIF([2]PREAGG_IXR_R6v2!A:A,A37,[2]PREAGG_IXR_R6v2!D:D)+SUMIF([2]CSG_V1!A:A,A37,[2]CSG_V1!D:D)+SUMIF([2]ESA!A:A,A37,[2]ESA!D:D)+SUMIF([2]Accessories!A:A,A37,[2]Accessories!D:D) -> #VALUE! | E37: 3HE13956AA | F37: XMA-SR-s 3.6T 36pt QSFP28 CR | G37: 1 | I37: =C37*G37 -> #VALUE!
A38: 3HE11307AA | B38: XMA - SR-s 2.4T 36pt QSFP28 CR to 3.6T | C38: =SUMIF('[2]AGGREGATION to PREAGG_Migration'!A:A,A38,'[2]AGGREGATION to PREAGG_Migration'!D:D)+SUMIF('[2]SR12E&SR7_Card Expansion'!A:A,A38,'[2]SR12E&SR7_Card Expansion'!D:D)+SUMIF('[2]IXR Card Expansion'!A:A,A38,'[2]IXR Card Expansion'!D:D)+SUMIF([2]PREAGG_v2_SR7B!A:A,A38,[2]PREAGG_v2_SR7B!D:D)+SUMIF([2]PREAGG_IXR_R6v2!A:A,A38,[2]PREAGG_IXR_R6v2!D:D)+SUMIF([2]CSG_V1!A:A,A38,[2]CSG_V1!D:D)+SUMIF([2]ESA!A:A,A38,[2]ESA!D:D)+SUMIF([2]Accessories!A:A,A38,[2]Accessories!D:D) -> #VALUE! | E38: 3HE11307AA | F38: XMA - SR-s 2.4T 36pt QSFP28 CR to 3.6T | G38: 1 | I38: =C38*G38 -> #VALUE!
A39: 3HE13956BA | B39: XMA-SR-s 3.6T 36pt QSFP28 ER | C39: =SUMIF('[2]AGGREGATION to PREAGG_Migration'!A:A,A39,'[2]AGGREGATION to PREAGG_Migration'!D:D)+SUMIF('[2]SR12E&SR7_Card Expansion'!A:A,A39,'[2]SR12E&SR7_Card Expansion'!D:D)+SUMIF('[2]IXR Card Expansion'!A:A,A39,'[2]IXR Card Expansion'!D:D)+SUMIF([2]PREAGG_v2_SR7B!A:A,A39,[2]PREAGG_v2_SR7B!D:D)+SUMIF([2]PREAGG_IXR_R6v2!A:A,A39,[2]PREAGG_IXR_R6v2!D:D)+SUMIF([2]CSG_V1!A:A,A39,[2]CSG_V1!D:D)+SUMIF([2]ESA!A:A,A39,[2]ESA!D:D)+SUMIF([2]Accessories!A:A,A39,[2]Accessories!D:D) -> #VALUE! | E39: 3HE13956BA | F39: XMA-SR-s 3.6T 36pt QSFP28 ER | G39: 1 | I39: =C39*G39 -> #VALUE!
A40: 3HE12388BA | B40: XMA - SR-s 2.4T 24pt QSFP28 ER | C40: =SUMIF('[2]AGGREGATION to PREAGG_Migration'!A:A,A40,'[2]AGGREGATION to PREAGG_Migration'!D:D)+SUMIF('[2]SR12E&SR7_Card Expansion'!A:A,A40,'[2]SR12E&SR7_Card Expansion'!D:D)+SUMIF('[2]IXR Card Expansion'!A:A,A40,'[2]IXR Card Expansion'!D:D)+SUMIF([2]PREAGG_v2_SR7B!A:A,A40,[2]PREAGG_v2_SR7B!D:D)+SUMIF([2]PREAGG_IXR_R6v2!A:A,A40,[2]PREAGG_IXR_R6v2!D:D)+SUMIF([2]CSG_V1!A:A,A40,[2]CSG_V1!D:D)+SUMIF([2]ESA!A:A,A40,[2]ESA!D:D)+SUMIF([2]Accessories!A:A,A40,[2]Accessories!D:D) -> #VALUE! | E40: 3HE12388BA | F40: XMA - SR-s 2.4T 24pt QSFP28 ER | G40: 1 | I40: =C40*G40 -> #VALUE!
...

Sheet Customer BoQ
A1: Vendor's Code | B1: Unit Description | C1: Unit Price | D1: Du Item Code | E1: Vendor's Code
A2: AGGv1 Bundle | B2: Nokia SR-7s - AGG v1 Bundle including: (1) 3HE16196AA BNDL 7750 SR-7s CPM2-7s CNTL RED DC PWR (1) 3HE12328AA ACC - SR-7s/14s PWR SHELF ACC KIT LVDC (1) 3HE12460AA ACC - 7750 SR-7s AIR FILTER DOOR KIT (3) 3HE12378AA ACC - 7750 SR-7s XCM IMPEDANCE PNL (2) 3HE11305AA XCM - 7750 SR-s XCM-7s (2) 3HE14027BA IOM-s - SR-s IOM-s 3.0T - ER | C2: 100000 | D2: 3013258069 | E2: AGGv1 Bundle
A3: AGGv2 Bundle | B3: Nokia SR-7s - AGG v2 Bundle including: (1) 3HE16196AA BNDL 7750 SR-7s CPM2-7s CNTL RED DC PWR (1) 3HE12328AA ACC - SR-7s/14s PWR SHELF ACC KIT LVDC (1) 3HE12460AA ACC - 7750 SR-7s AIR FILTER DOOR KIT (3) 3HE12378AA ACC - 7750 SR-7s XCM IMPEDANCE PNL (2) 3HE11305AA XCM - 7750 SR-s XCM-7s (2) 3HE12510BA IOM-s - SR-s IOM-s 1.6T - ER | C3: 90000 | D3: 3031328909 | E3: AGGv2 Bundle
A4: AGGv3 Bundle | B4: Nokia SR-2s - AGG v3 Bundle including: (1) 3HE14032AA BNDL - 7750 SR-2s LVDC (1) 3HE12519AA ACC - 7750 SR-2s AIR FILTER KIT (1) 3HE14029AA ACC - 7750 SR-s MDA-s IMPEDANCE PANEL (2) 3HE12379AA XCM - 7750 SR-s XCM-2s (2) 3HE12510BA IOM-s - SR-s IOM-s 1.6T - ER | C4: 75000 | D4: 3063372685 | E4: AGGv3 Bundle
A5: AGGv1 400G Bundle | B5: AGG 400G MDA-s bundle including: (1) 3HE12515AA MDA-s – SR-s 4-pt QSFP-DD + 4-pt QSFP28 (4) 3HE15212AA QSFP56-DD - 400G LR8 10Km 0/70C - each with 3HE00400PP - RTU License for 400G port (2) 3HE10550AA QSFP28 - 100GBASE-LR4 ROHS6/6 0/70C - each with 3HE00100PP - RTU License for 100G port | C5: 44000 | D5: 3073693538 | E5: AGGv1 400G Bundle
A6: AGGv3 400G Bundle | B6: AGG 400G MDA-s bundle including: (1) 3HE12515AA MDA-s – SR-s 4-pt QSFP-DD + 4-pt QSFP28 (2) 3HE15212AA QSFP56-DD - 400G LR8 10Km 0/70C - each with 3HE00400PP - RTU License for 400G port (4) 3HE10550AA QSFP28 - 100GBASE-LR4 ROHS6/6 0/70C - each with 3HE00100PP - RTU License for 100G port | C6: 30117.36 | D6: 3062610663 | E6: AGGv3 400G Bundle
A7: AGG 100G Bundle1 | B7: AGG 100G MDA-s Bundle including: (1) 3HE12511AA MDA-s - SR-s 18-pt QSFP28 (12) 3HE10550AA QSFP28 - 100GBASE-LR4 ROHS6/6 0/70C - each with 3HE00100PP - RTU License for 100G port | C7: 36520 | D7: 3076787939 | E7: AGG 100G Bundle1
A8: AGG 100G Bundle2 | B8: AGG 100G MDA-s bundle including: (1) 3HE12511AA MDA-s - SR-s 18-pt QSFP28 (4) 3HE10550AA QSFP28 - 100GBASE-LR4 ROHS6/6 0/70C - each with 3HE00100PP - RTU License for 100G port | C8: 22657.2 | D8: 3093678645 | E8: AGG 100G Bundle2
A9: AGG 100G&25G Bundle | B9: AGG 100G/25G MDA-s Bundle_v1 including: (1) 3HE12513AA MDA-s - 16pt SFP-DD MACsec + 4pt QSFP28 (4) 3HE10550AA QSFP28 - 100GBASE-LR4 ROHS6/6 0/70C - each with 3HE00100PP - RTU License for 100G port (8) 3HE14835AA SFP28 25GE LR - LC ROHS6/6 -40/85C - each with 3HE00025PP - RTU License for 25G port (4) 3HE15377AA SFP28 - 25GE ER - LC ROHS6/6 -40/85C - each with 3HE00100PP - RTU License for 25G port | C9: 27500 | D9: 3065765496 | E9: AGG 100G&25G Bundle
A10: ESA Bundle | B10: AGG ESA Bundle for Ipsec including: (1) 3HE15841AA ESA - 7750 SR ESA 100G DC (2) 3HE10551AA QSFP28 - 100GBASE-SR4 ROHS6/6 0/70C - each with 3HE00100PP - RTU License for 100G port | C10: 13860 | D10: 3071025782 | E10: ESA Bundle
A11: 3HE12392AA | B11: XMA - SR-s 4.8T 36pt QSFP-DD CR to 12T | C11: 40000 | D11: 3085299903 | E11: 3HE12392AA
A12: 3HE12390AA | B12: XMA - SR-s 3.6T 36pt QSFP-DD CR | C12: 30000 | D12: 3085522104 | E12: 3HE12390AA
A13: 3HE13956AA | B13: XMA-SR-s 3.6T 36pt QSFP28 CR | C13: 26000 | D13: 3011417115 | E13: 3HE13956AA
... A16: 3HE12388BA | B16: XMA - SR-s 2.4T 24pt QSFP28 ER | C16: 48000 | D16: 3010409766 | E16: 3HE12388BA
A17: 3HE12526BA | B17: XMA - SR-s 1.2T 18pt QSFP28 ER to 1.8T | C17: 26000 | D17: #N/A | E17: 3HE12526BA
A18: 3HE12525BA | B18: XMA - SR-s 1.2T 12pt QSFP28 ER | C18: 24000 | D18: 3010866762 | E18: 3HE12525BA
A19: 3HE11305AA | B19: XCM - 7750 SR-s XCM-7s | C19: 11600 | D19: 3068077766 | E19: 3HE11305AA
A20: 3HE12379AA | B20: XCM - 7750 SR-s XCM-2s | C20: 14000 | D20: 3087565806 | E20: 3HE12379AA
A21: 3HE14027BA | B21: IOM-s - SR-s IOM-s 3.0T - ER | C21: 59250 | D21: 3074418269 | E21: 3HE14027BA
A22: 3HE12510BA | B22: IOM-s - SR-s IOM-s 1.6T - ER | C22: 32000 | D22: 3022852775 | E22: 3HE12510BA
A23: 3HE15563AA | B23: MDA-s - SR-s 2pt QSFP-DD + 2pt QSFP28 | C23: 8500 | D23: 3088379579 | E23: 3HE15563AA
A24: 3HE12511AA | B24: MDA-s - SR-s 18-pt QSFP28 | C24: 17250 | D24: 3070977509 | E24: 3HE12511AA
A25: 3HE12513AA | B25: MDA-s - 16pt SFP-DD MACsec + 4pt QSFP28 | C25: 16750 | D25: 3086323707 | E25: 3HE12513AA
A26: 3HE15562AA | B26: MDA-s - 8pt SFP-DD MACsec + 2pt QSFP28 | C26: 8500 | D26: 3040867359 | E26: 3HE15562AA
A27: 3HE12515AA | B27: MDA-s – SR-s 4-pt QSFP-DD + 4-pt QSFP28 | C27: 16750 | D27: 3056682874 | E27: 3HE12515AA
A28: AGG_SR12E_Upgrade_400G | B28: 7750 SR-7/12e AGG 400G IOM5 + MDA-e-XP card Bundle including: (1) 3HE12332BA IOM - 7750 SR IOM5-e - ER (2) 3HE15152AA MDA-e-XP - 7750 SR 6-pt QSFP-DD (8) 3HE15212AA QSFP56-DD - 400G LR8 10Km 0/70C - each with 3HE00100PP - RTU License for 400G port (10) 3HE10550AA QSFP28 - 100GBASE-LR4 ROHS6/6 0/70C - each with 3HE00100PP - RTU License for 100G port | C28: 70584.291 | D28: 3086200344 | E28: AGG_SR12E_Upgrade_400G
A29: AGG_SR12E_Upgrade_100G | B29: 7750 SR-7/12e 100G MDA-e-XP Bundle including: (1) 3HE12333AA MDA-e-XP - 7750 SR 6-pt QSFP28 (2) 3HE10550AA QSFP28 - 100GBASE-LR4 ROHS6/6 0/70C - each with 3HE00100PP - RTU License for 100G port (1) 3HE11239AA QSFP28 - 100GBase-ER4Lite RoHS6/6 0/70C - each with 3HE00100PP - RTU License for 100G port | C29: 18196.08 | D29: 3021402263 | E29: AGG_SR12E_Upgrade_100G
... A212: Power_PowerCables and Lugs | B212: Power upgrade cable and lugs kit for Core/AGGR/PAGG/Access routers (green, blue and red) | C212: 68.49 | D212: 3045568832 | E212: Power_PowerCables and Lugs
A213: Upgrade the BNG node from Release 16 to Release 22 | C213: 3984 | D213: 3025958050 | E213: Upgrade the BNG node from Release 16 to Release 22
A214: Deliver custom software artefacts of sixteen sprints | C214: 966604.8 | D214: 3083845282 | E214: Deliver custom software artefacts of sixteen sprints
A215: Implementation of VAS for subscriber based firewall enablement for 1 AGGR pair | C215: 18300 | D215: 3025958047 | E215: Implementation of VAS for subscriber based firewall enablement for 1 AGGR pair
A216: Deliver custom software artefacts of twenty-four sprints | C216: 1371955.2 | D216: 3083845283 | E216: Deliver custom software artefacts of twenty-four sprints
A217: Deliver custom software artefacts of eight sprints | C217: 537600 | D217: 3083845281 | E217: Deliver custom software artefacts of eight sprints
A218: Deliver custom software artefacts of sixteen sprints | C218: 966604.8 | D218: 3083845282 | E218: Deliver custom software artefacts of sixteen sprints
A219: Deliver custom software artefacts of one sprint | C219: 74088 | D219: 3083845280 | E219: Deliver custom software artefacts of one sprint
A220: Design Update on BNG for VAS (subcriber based firewall enablement), Design validation and lab testing | C220: 27057.44 | D220: 3025958046 | E220: Design Update on BNG for VAS (subcriber based firewall enablement), Design validation and lab testing

Sheet BPO
A5: Line | B5: Type | C5: Item/Job | D5: Nokia code | E5: Supplier Item | F5: Description | G5: UOM | H5: Price | I5: Qty | J5: Total Price
A6: 5 | B6: Goods | C6: 3062610663 | D6: =VLOOKUP(C6,'Customer BoQ'!$D$2:$E$220,2,0) -> AGGv3 400G Bundle | F6: AGG400G MDAs BNDL incl:(1)3HE12515AA MDAs SRs 4pt QSFP-DD+4pt QSFP28 (2)3HE15212AA QSFP56-DD400G LR8 10Km 0/70C-each_w_3HE00400PP-RTU Lic.for 400G port (4)3HE10550AA QSFP28-100GBASE-LR4 ROHS6/6 0/70C-each_w_3HE00100PP-RTU Lic.for 100G port | G6: Each | H6: 30117.36
A7: 102 | B7: Goods | C7: 3078335361 | D7: =VLOOKUP(C7,'Customer BoQ'!$D$2:$E$220,2,0) -> 3HE14632AA | F7: 1588 Freq & Phase, IXR-e Big | G7: Each | H7: 100
A8: 202 | B8: Goods | C8: 3017953528 | D8: =VLOOKUP(C8,'Customer BoQ'!$D$2:$E$220,2,0) -> Schneider/Nader Output Breakers (Standard-Type) - 63A | F8: Supply of Schneider/Nader Output Breakers (Standard-Type) - 63A | G8: Each | H8: 3.39
A9: 75 | B9: Goods | C9: 3061242563 | D9: =VLOOKUP(C9,'Customer BoQ'!$D$2:$E$220,2,0) -> 3HE09327AA | F9: SFP+ 10GE LR - LC ROHS6/6-40/85C - each with 3HE00100PP - RTU License for 10G port | G9: Each | H9: 1462
A10: 212 | B10: Goods | C10: 3063746227 | D10: =VLOOKUP(C10,'Customer BoQ'!$D$2:$E$220,2,0) -> CSG Link Shifting | F10: CSG Link Shiting includes conneting the uplink as single homed, shifting the uplink from one PAGG to another | G10: Each | H10: 1800
A11: 150 | B11: Goods | C11: 3043171899 | D11: =VLOOKUP(C11,'Customer BoQ'!$D$2:$E$220,2,0) -> Testbed Service | F11: POC service including POC Desing ,POC implementation ,POC execution | G11: Each | H11: 0
A12: 141 | B12: Goods | C12: 3074240543 | D12: =VLOOKUP(C12,'Customer BoQ'!$D$2:$E$220,2,0) -> CSG_v3 HW Installation & Commissioning | F12: Nokia-CSG-New_v3-HW-Installation includes Project Management teams,Rollout team,Warehouse rental, site survey, installation, comissioning, Integration and Decomissioning services | G12: Each | H12: 2004
A13: 92 | B13: Goods | C13: 3073795830 | D13: =VLOOKUP(C13,'Customer BoQ'!$D$2:$E$220,2,0) -> 3HE15809AA | F13: SR - OS - ZTP 7750/7950 R20.x LICENSE | G13: Each | H13: 1000
A14: 142 | B14: Goods | C14: 3097407090 | D14: =VLOOKUP(C14,'Customer BoQ'!$D$2:$E$220,2,0) -> CSG_v3 Migration | F14: Nokia-CSG-New_v3-Migration includes Migration execution ,testing and acceptance services | G14: Each | H14: 988
A15: 123 | B15: Goods | C15: 3098864750 | D15: =VLOOKUP(C15,'Customer BoQ'!$D$2:$E$220,2,0) -> SWAP Aggregation_PE_v1 (Replacement/Upgrade) Hot SWAP Migration | F15: Nokia AGG-HOT SWAP-Migration_v1 incl. Automated Migration execution, testing and acceptance services | G15: Each | H15: 0
A16: 207 | B16: Goods | C16: 3030879119 | D16: =VLOOKUP(C16,'Customer BoQ'!$D$2:$E$220,2,0) -> Minor Upgrade of existing power system. ( Busbar - Cabling, etc ) | F16: "Minor Upgrade of existing power system. ( Busbar, | G16: Each | H16: 5601.75
A17: 74 | B17: Goods | C17: 3029033430 | D17: =VLOOKUP(C17,'Customer BoQ'!$D$2:$E$220,2,0) -> 3HE15377AA | F17: SFP28 - 25GE ER - LC ROHS6/6 -40/85C - each with 3HE00100PP - RTU License for 25G port | G17: Each | H17: 1713
... A190: 182 | B190: Goods | C190: 3082379855 | D190: =VLOOKUP(C190,'Customer BoQ'!$D$2:$E$220,2,0) -> Nokia-Power-Upgrade- Single Battery Cell Addition- Hardware (170 Ah) | F190: Power upgrade battery kit for Pre-Aggr routers (170 Ah) 12V Cell | G190: Each | H190: 272.5
A191: 126 | B191: Goods | C191: 3075706519 | D191: =VLOOKUP(C191,'Customer BoQ'!$D$2:$E$220,2,0) -> Nokia AGG-SWAP-Port by Port Migration from multiple nodes to Nokia AGG within the same site | F191: Nokia AGG- SWAP-Port by Port Migration incl. Automated Migration execution, testing and acceptance services [from multiple nodes to Nokia AGG within the same site [up to 3 nodes]for maximum of 10 ports] | G191: Each | H191: 10000 | I191: 12 | J191: =H191*I191 -> 120000
A192: 46 | B192: Goods | C192: 3084370884 | D192: =VLOOKUP(C192,'Customer BoQ'!$D$2:$E$220,2,0) -> IXR 100G to 400G Upgrade Bundle | F192: "7250 IXR-R6 400G upgrade Bundle | G192: Each | H192: 63000
A193: 179 | B193: Goods | C193: 3083057969 | D193: =VLOOKUP(C193,'Customer BoQ'!$D$2:$E$220,2,0) -> 3BK08958BA | F193: Power Cable 1x35 Blue (15 meters per site) | G193: Each | H193: 5.81
A194: 191 | B194: Goods | C194: 3011573128 | D194: =VLOOKUP(C194,'Customer BoQ'!$D$2:$E$220,2,0) -> ODF Patch panels (72) | F194: 72 PORT 4U (72 pcs Simplex SC/APC adaptors, 72 pcs SC/APC Pigtail, 72 pcs splice protector sleeve) | G194: Each | H194: 1443.75
A195: 93 | B195: Goods | C195: 3098721057 | D195: =VLOOKUP(C195,'Customer BoQ'!$D$2:$E$220,2,0) -> 3HE15662BA | F195: OS - 7250 IXR R20.x ZTP OS LICENSE LARGE | G195: Each | H195: 300
A196: 40 | B196: Goods | C196: 3039441163 | D196: =VLOOKUP(C196,'Customer BoQ'!$D$2:$E$220,2,0) -> SCSG_Low Bundle1 | F196: "IXR-R6-Low1 | G196: Each | H196: 26987.98
A197: 177 | B197: Goods | C197: 3077725595 | D197: =VLOOKUP(C197,'Customer BoQ'!$D$2:$E$220,2,0) -> 1AD147550002 | F197: 100 Amps Circuit Breakers (Considered for controller sites) | G197: Each | H197: 211
A198: 69 | B198: Goods | C198: 3027907052 | D198: =VLOOKUP(C198,'Customer BoQ'!$D$2:$E$220,2,0) -> 3HE10551AA | F198: QSFP28 - 100GBASE-SR4 ROHS6/6 0/70C - each with 3HE00100PP - RTU License for 100G port | G198: Each | H198: 2000
A199: 161 | B199: Goods | C199: 3050707920 | D199: =VLOOKUP(C199,'Customer BoQ'!$D$2:$E$220,2,0) -> Nokia-OS-Upgrade-AGG-Service | F199: Upgrade the AGG node from N Release to N+1 Release | G199: Each | H199: 1548.8
A200: 151 | B200: Goods | C200: 3027390070 | D200: =VLOOKUP(C200,'Customer BoQ'!$D$2:$E$220,2,0) -> Nokia-Design-Service | F200: Design includes Customer Workshop,HLD,LLD,Acceptance Test book,SAM design,Configuration templates,Migration strategy,MOP templates. | G200: Each | H200: 0
A201: 89 | B201: Goods | C201: 3016646068 | D201: =VLOOKUP(C201,'Customer BoQ'!$D$2:$E$220,2,0) -> 100G/400G Amplifier Bundle | F201: "Amplifier Bundle including: | G201: Each | H201: 4337.8
A202: 18 | B202: Goods | C202: 3068077766 | D202: =VLOOKUP(C202,'Customer BoQ'!$D$2:$E$220,2,0) -> 3HE11305AA | F202: XCM - 7750 SR-s XCM-7s | G202: Each | H202: 11600
A203: 65 | B203: Goods | C203: 3084862463 | D203: =VLOOKUP(C203,'Customer BoQ'!$D$2:$E$220,2,0) -> 3HE16564AA | F203: QSFP-DD ZR each with 3HE00100PP - RTU License for 400G port | G203: Each | H203: 7300
... A205: 132 | B205: Goods | C205: 3098507232 | D205: =VLOOKUP(C205,'Customer BoQ'!$D$2:$E$220,2,0) -> SWAP PAGG/SCSG HW Installation & Commissioning | F205: Nokia PAGG/SCSG-SWAP-HW installation incl. Project Management teams, Rollout team, Warehouse rental, site survey, installation, commissioning, Integration, ATP, and Decommissioning services | G205: Each | H205: 6000
A206: 144 | B206: Goods | C206: 3015616247 | D206: =VLOOKUP(C206,'Customer BoQ'!$D$2:$E$220,2,0) -> 3rd Party CSG Migration | F206: 3rd party CSG-Remote migration includes Migration execution ,testing and acceptance services | G206: Each | H206: 500 | I206: 112 | J206: =H206*I206 -> 56000
A207: 100 | B207: Goods | C207: 3015902050 | D207: =VLOOKUP(C207,'Customer BoQ'!$D$2:$E$220,2,0) -> 3HELB019AA | F207: RTU - 1588 Freq & Phase LICENSE LARGE | G207: Each | H207: 100
A208: 213 | B208: Goods | C208: 3083845280 | D208: =VLOOKUP(C208,'Customer BoQ'!$D$2:$E$220,2,0) -> Deliver custom software artefacts of one sprint | F208: Deliver custom software artefacts of one sprint | G208: Each | H208: 74088 | I208: 2 | J208: =H208*I208 -> 148176
A209: 217 | B209: Goods | C209: 3083845280 | D209: =VLOOKUP(C209,'Customer BoQ'!$D$2:$E$220,2,0) -> Deliver custom software artefacts of one sprint | F209: Deliver custom software artefacts of one sprint | G209: Each | H209: 74088
A210: 117 | B210: Goods | C210: 3085159011 | D210: =VLOOKUP(C210,'Customer BoQ'!$D$2:$E$220,2,0) -> 3HENSPTSC | F210: NSP TSC Module | G210: Each | H210: 200000
A211: 128 | B211: Goods | C211: 3076929792 | D211: =VLOOKUP(C211,'Customer BoQ'!$D$2:$E$220,2,0) -> Nokia AGG-SWAP-Port by Port Migration from multiple nodes to Nokia AGG from a different physical site | F211: Nokia AGG- SWAP-Port by Port Migration incl. Automated Migration execution, testing and acceptance services [from multiple nodes to Nokia AGG from a different physical site [up to 3 nodes]for maximum of 10 ports] | G211: Each | H211: 10000
A212: 73 | B212: Goods | C212: 3064946462 | D212: =VLOOKUP(C212,'Customer BoQ'!$D$2:$E$220,2,0) -> 3HE14835AA | F212: SFP28 25GE LR - LC ROHS6/6 -40/85C - each with 3HE00100PP - RTU License for 25G port | G212: Each | H212: 1370.63
A213: 24 | B213: Goods | C213: 3086323707 | D213: =VLOOKUP(C213,'Customer BoQ'!$D$2:$E$220,2,0) -> 3HE12513AA | F213: MDA-s - 16pt SFP-DD MACsec + 4pt QSFP28 | G213: Each | H213: 16750
A214: 221 | B214: Goods | C214: 3025958046 | D214: =VLOOKUP(C214,'Customer BoQ'!$D$2:$E$220,2,0) -> Design Update on BNG for VAS (subcriber based firewall enablement), Design validation and lab testing | F214: Design Update on BNG for VAS (subcriber based firewall enablement), Design validation and lab testing | G214: Each | H214: 27057.44
A215: 223 | B215: Goods | C215: 3025958048 | D215: =VLOOKUP(C215,'Customer BoQ'!$D$2:$E$220,2,0) -> #N/A | F215: RTU - SROS ADV DC GW and Svc Chain | G215: Each | H215: 9000
A216: 45 | B216: Goods | C216: 3079190070 | D216: =VLOOKUP(C216,'Customer BoQ'!$D$2:$E$220,2,0) -> SCSG_10G_Bundle | F216: "7250 IXR-R6 Low 10G BNDL incl: | G216: Each | H216: 7598
A217: 21 | B217: Goods | C217: 3022852775 | D217: =VLOOKUP(C217,'Customer BoQ'!$D$2:$E$220,2,0) -> 3HE12510BA | F217: IOM-s - SR-s IOM-s 1.6T - ER | G217: Each | H217: 32000
...

Sheet SUMMARY
F5: Model Type | G5: Qty | H5: Price
F6: Synch Source | H6: ='Synch Source'!F4 -> 177674.72
F7: vRR Server Replacement Services | H7: 90000
F8: Fixed Switch Migration | H8: ='Fixed Switch Migration'!F3 -> 56000
F9: TOTAL | H9: =SUM(H6:H8) -> 323674.72

Sheet Synch Source
A1: PN | B1: Du PN | C1: Description | D1: Price | E1: Qty | F1: Total Price
A2: Design | C2: Nokia Design for synch source change on AGGR (including design discussions, lab preparation, lab testing, interop testing, HLD-LLD Update , design validation, dry&run, ATP, High level Migration strategy and validation) | D2: 37674.72 | E2: 1 | F2: =D2*E2 -> 37674.72
A3: Nokia AGG-SWAP-Port by Port Migration from multiple nodes to Nokia AGG from a different physical site | B3: 3075706519 | C3: =VLOOKUP(A3,'Customer BoQ'!A:B,2,0) -> Nokia AGG- SWAP-Port by Port Migration incl. Automated Migration execution, testing and acceptance services [from multiple nodes to Nokia AGG from a different physical site [up to 3 nodes]for maximum of 10 ports] | D3: =VLOOKUP(A3,'Customer BoQ'!A:C,3,0) -> 10000 | E3: 14 | F3: =D3*E3 -> 140000
F4: =SUM(F2:F3) -> 177674.72
A8: Inclusions
A9: Changing AGGR Synch Source to TP4100 on 36 AGGRs
A12: Exclusions:
A13: Phase sync enabling on downlinks [SCSGs/CSGs directly connected to AGGRs]
A14: Changing nodes which are currently synced with PTP to Sync-e (PREAGGs)
A16: * PTP to Synch-e configuration on PREAGGs should be completed prior to the activity.
C20: Category | D20: Number
C21: Number of AGGRs which have AGG neighborship (will be included) | D21: 36
C22: Number of AGGRs which has Core Only Connectivity (Will be excluded) | D22: 34
C23: Number of AGGRs which will be offloaded (Will be excluded) | D23: 8
A25: AGGR Will be included in the scope (8*AGGR will be removed from the below list which does not have TP4100 connections)
A26: node name | C26: system¬ipv4
A27: SHJ-6002-AGGR-SR7-1 | C27: 10.65.0.29
A28: SHJ-6002-AGGR-SR7-2 | C28: 10.65.0.30
A29: AUH-2903-AGGR-SR7-1 | C29: 10.65.0.39
A30: AUH-2903-AGGR-SR7-2 | C30: 10.65.0.40
A31: AUH-1416-AGGR-SR12E-1 | C31: 10.65.0.41
A32: AUH-1416-AGGR-SR12E-2 | C32: 10.65.0.42
A33: AUH-5002-AGGR-SR7-1 | C33: 10.65.0.45
A34: AUH-5002-AGGR-SR7-2 | C34: 10.65.0.46
A35: AUH-6005-AGGR-SR12e-1 | C35: 10.65.0.47
A36: AUH-6005-AGGR-SR12e-2 | C36: 10.65.0.48
A37: AUH-6003-AGGR-SR7B-1 | C37: 10.65.0.49
... A70: DXB-5008-AGGR-SR2S-2 | C70: 10.65.0.136

Sheet Fixed Switch Migration
A1: PN | B1: Du PN | C1: Description | D1: Price | E1: Qty | F1: Total Price
A2: 3rd Party CSG Migration | B2: 3015616247 | C2: =VLOOKUP(A2,'Customer BoQ'!A:B,2,0) -> 3rd party CSG-Remote migration includes Migration execution ,testing and acceptance services | D2: =VLOOKUP(A2,'Customer BoQ'!A:C,3,0) -> 500 | E2: 112 | F2: =D2*E2 -> 56000
A3: TOTAL | F3: =F2 -> 56000
A6: * Nokia to support Cisco during the MW to shutdown the port from Nokia PREAGG.
A7: * BoQ is limited to 17*MW. (2*MW added as buffer).
A8: * 102xSwitches & 10xDirectly connected fixed services will be migrated in 15*MW within 3 months.
A9: * CR Management / PIP will be under Cisco responsibility.
A11: Service Type | B11: Ports
A12: Switches | B12: 102
A13: Directly Connected Fixed Services | B13: 10
A14: Total Ports | B14: 112

Sheet vRR Server Replacement
A1: PN | C1: Description | D1: Price | E1: Qty | F1: Total Price
A2: Services | C2: Installation, testing, Acceptance, migration | D2: 90000 | E2: 1 | F2: =D2*E2 -> 90000
F3: =SUM(F2:F2) -> 90000
A6: * 2 vRR in 3 regions; 6 live deployments. 2 will be installed in lab and 1 will handed over to operations as spare.
A7: * Dismantled 9xSN7 servers will be collected by Nokia.
A8: * Replacement PIP will be shared.
