Workbook

Sheet Executive Dashboard
B1: GIS NETWORK INFRASTRUCTURE — EXECUTIVE DASHBOARD
B2: Site Database Overview | AUH • AAN • DXB • NE • WR | January 2024 | F2: 5G Network Penetration: | H2: =D5/B5 -> 0.80035166
B5: =COUNTA('Master Sheet'!A2:A6257) -> 6256 | D5: =COUNTIFS('Master Sheet'!K2:K6257,"On Air") -> 5007 | F5: =COUNTIFS('Master Sheet'!J2:J6257,"On Air") -> 6208 | H5: =COUNTIFS('Master Sheet'!I2:I6257,"On Air") -> 6221
B6: TOTAL SITES | D6: 5G ON-AIR | F6: 4G ON-AIR | H6: 3G ON-AIR
B9: REGIONAL SITE DISTRIBUTION
B10: Region | C10: Total Sites | J10: Region | K10: Total Sites | L10: 5G On-Air | M10: 4G On-Air | N10: 3G On-Air
B11: AAN | C11: =K11 -> 739 | J11: Al Ain (AAN) | K11: =COUNTIFS('Master Sheet'!C2:C6257,"AAN") -> 739 | L11: =COUNTIFS('Master Sheet'!C2:C6257,"AAN",'Master Sheet'!K2:K6257,"On Air") -> 551 | M11: =COUNTIFS('Master Sheet'!C2:C6257,"AAN",'Master Sheet'!J2:J6257,"On Air") -> 738 | N11: =COUNTIFS('Master Sheet'!C2:C6257,"AAN",'Master Sheet'!I2:I6257,"On Air") -> 738
B12: AUH | C12: =K12 -> 1400 | J12: Abu Dhabi (AUH) | K12: =COUNTIFS('Master Sheet'!C2:C6257,"AUH") -> 1400 | L12: =COUNTIFS('Master Sheet'!C2:C6257,"AUH",'Master Sheet'!K2:K6257,"On Air") -> 1179 | M12: =COUNTIFS('Master Sheet'!C2:C6257,"AUH",'Master Sheet'!J2:J6257,"On Air") -> 1386 | N12: =COUNTIFS('Master Sheet'!C2:C6257,"AUH",'Master Sheet'!I2:I6257,"On Air") -> 1393
B13: DXB | C13: =K13 -> 1911 | J13: Dubai (DXB) | K13: =COUNTIFS('Master Sheet'!C2:C6257,"DXB") -> 1911 | L13: =COUNTIFS('Master Sheet'!C2:C6257,"DXB",'Master Sheet'!K2:K6257,"On Air") -> 1726 | M13: =COUNTIFS('Master Sheet'!C2:C6257,"DXB",'Master Sheet'!J2:J6257,"On Air") -> 1900 | N13: =COUNTIFS('Master Sheet'!C2:C6257,"DXB",'Master Sheet'!I2:I6257,"On Air") -> 1886
B14: NE | C14: =K14 -> 1714 | J14: Northern Emirates (NE) | K14: =COUNTIFS('Master Sheet'!C2:C6257,"NE") -> 1714 | L14: =COUNTIFS('Master Sheet'!C2:C6257,"NE",'Master Sheet'!K2:K6257,"On Air") -> 1347 | M14: =COUNTIFS('Master Sheet'!C2:C6257,"NE",'Master Sheet'!J2:J6257,"On Air") -> 1706 | N14: =COUNTIFS('Master Sheet'!C2:C6257,"NE",'Master Sheet'!I2:I6257,"On Air") -> 1714
B15: WR | C15: =K15 -> 492 | J15: Western Region (WR) | K15: =COUNTIFS('Master Sheet'!C2:C6257,"WR") -> 492 | L15: =COUNTIFS('Master Sheet'!C2:C6257,"WR",'Master Sheet'!K2:K6257,"On Air") -> 204 | M15: =COUNTIFS('Master Sheet'!C2:C6257,"WR",'Master Sheet'!J2:J6257,"On Air") -> 478 | N15: =COUNTIFS('Master Sheet'!C2:C6257,"WR",'Master Sheet'!I2:I6257,"On Air") -> 490
J16: TOTAL | K16: =SUM(K11:K15) -> 6256 | L16: =SUM(L11:L15) -> 5007 | M16: =SUM(M11:M15) -> 6208 | N16: =SUM(N11:N15) -> 6221
B18: TECHNOLOGY & VENDOR ANALYSIS | J18: 5G PENETRATION BY REGION
B19: Technology Stack | C19: Sites | J19: Region | K19: Total Sites | L19: 5G On-Air | M19: 5G Penetration | N19: Gap to 100%
B20: 2G+3G+4G+5G | C20: =COUNTIFS('Master Sheet'!W2:W6257,"2G+3G+4G+5G") -> 2476 | J20: Al Ain (AAN) | K20: =K11 -> 739 | L20: =L11 -> 551 | M20: =L20/K20 -> 0.74560217 | N20: =K20-L20 -> 188
B21: 3G+4G+5G | C21: =COUNTIFS('Master Sheet'!W2:W6257,"3G+4G+5G") -> 2503 | J21: Abu Dhabi (AUH) | K21: =K12 -> 1400 | L21: =L12 -> 1179 | M21: =L21/K21 -> 0.84214286 | N21: =K21-L21 -> 221
B22: 3G+4G | C22: =COUNTIFS('Master Sheet'!W2:W6257,"3G+4G") -> 791 | J22: Dubai (DXB) | K22: =K13 -> 1911 | L22: =L13 -> 1726 | M22: =L22/K22 -> 0.90319205 | N22: =K22-L22 -> 185
B23: 2G+3G+4G | C23: =COUNTIFS('Master Sheet'!W2:W6257,"2G+3G+4G") -> 414 | J23: Northern Emirates (NE) | K23: =K14 -> 1714 | L23: =L14 -> 1347 | M23: =L23/K23 -> 0.78588098 | N23: =K23-L23 -> 367
B24: 4G+5G | C24: =COUNTIFS('Master Sheet'!W2:W6257,"4G+5G") -> 26 | J24: Western Region (WR) | K24: =K15 -> 492 | L24: =L15 -> 204 | M24: =L24/K24 -> 0.41463415 | N24: =K24-L24 -> 288
B25: 3G | C25: =COUNTIFS('Master Sheet'!W2:W6257,"3G") -> 31 | J25: TOTAL | K25: =SUM(K20:K24) -> 6256 | L25: =SUM(L20:L24) -> 5007 | M25: =L25/K25 -> 0.80035166 | N25: =K25-L25 -> 1249
B26: 2G+3G | C26: =COUNTIFS('Master Sheet'!W2:W6257,"2G+3G") -> 8
B27: Other | C27: =B5-SUM(C20:C26) -> 7
B29: VENDOR DISTRIBUTION | J29: SITE INFRASTRUCTURE MIX
B30: Vendor | C30: Sites | D30: % Share | J30: Site Category | K30: Sites | L30: % Share
B31: Huawei | C31: =COUNTIFS('Master Sheet'!P2:P6257,"Huawei") -> 2749 | D31: =C31/SUM(C31:C36) -> 0.43941816 | J31: Greenfield | K31: =COUNTIFS('Master Sheet'!S2:S6257,"Greenfield")+COUNTIFS('Master Sheet'!S2:S6257,"Green Field")+COUNTIFS('Master Sheet'!S2:S6257,"GRD")+COUNTIFS('Master Sheet'!S2:S6257,"Greenfield (Du CAPEX)")+COUNTIFS('Master Sheet'!S2:S6257,"GF Site Share")+COUNTIFS('Master Sheet'!S2:S6257,"GF - Plam Tree")+COUNTIFS('Master Sheet'!S2:S6257,"Easy Macro - Greenfield")+COUNTIFS('Master Sheet'!S2:S6257,"Greenfield - Lamp Pole")+COUNTIFS('Master Sheet'!S2:S6257,"Green Field Palm Tree") -> 2676 | L31: =K31/SUM(K31:K35) -> 0.42774936
B32: Nokia | C32: =COUNTIFS('Master Sheet'!P2:P6257,"Nokia") -> 1736 | D32: =C32/SUM(C31:C36) -> 0.27749361 | J32: Rooftop | K32: =COUNTIFS('Master Sheet'!S2:S6257,"Rooftop")+COUNTIFS('Master Sheet'!S2:S6257,"Roof Top")+COUNTIFS('Master Sheet'!S2:S6257,"Micro RT")+COUNTIFS('Master Sheet'!S2:S6257,"Rooftop_Lamp Post")+COUNTIFS('Master Sheet'!S2:S6257,"Site Share - Rooftop")+COUNTIFS('Master Sheet'!S2:S6257,"Easy Macro - Rooftop") -> 1410 | L32: =K32/SUM(K31:K35) -> 0.22538363
B33: Nokia/Huawei | C33: =COUNTIFS('Master Sheet'!P2:P6257,"Nokia/Huawei") -> 884 | D33: =C33/SUM(C31:C36) -> 0.14130435 | J33: Site Sharing | K33: =COUNTIFS('Master Sheet'!S2:S6257,"Site Sharing")+COUNTIFS('Master Sheet'!S2:S6257,"SS OPEX")+COUNTIFS('Master Sheet'!S2:S6257,"SS CAPEX")+COUNTIFS('Master Sheet'!S2:S6257,"ETC Site Share")+COUNTIFS('Master Sheet'!S2:S6257,"ADNOC Tower Sharing")+COUNTIFS('Master Sheet'!S2:S6257,"Site Share")+COUNTIFS('Master Sheet'!S2:S6257,"Site Share - Palm Tree")+COUNTIFS('Master Sheet'!S2:S6257,"Site Share - RDU")+COUNTIFS('Master Sheet'!S2:S6257,"Site Share - Canopy Column")+COUNTIFS('Master Sheet'!S2:S6257,"Site Share - Mosaic")+COUNTIFS('Master Sheet'!S2:S6257,"Nedaa Share")+COUNTIFS('Master Sheet'!S2:S6257,"Site share_ETI Plot") -> 1691 | L33: =K33/SUM(K31:K35) -> 0.27030051
B34: Ericsson | C34: =COUNTIFS('Master Sheet'!P2:P6257,"Ericsson") -> 364 | D34: =C34/SUM(C31:C36) -> 0.058184143 | J34: Capex (du/ET) | K34: =COUNTIFS('Master Sheet'!S2:S6257,"Capex - du")+COUNTIFS('Master Sheet'!S2:S6257,"du CAPEX")+COUNTIFS('Master Sheet'!S2:S6257,"Capex_ETC Lead")+COUNTIFS('Master Sheet'!S2:S6257,"Capex_ETC Lead_Palm Tree")+COUNTIFS('Master Sheet'!S2:S6257,"ET Capex")+COUNTIFS('Master Sheet'!S2:S6257,"Capex_DU")+COUNTIFS('Master Sheet'!S2:S6257,"Capex ETI")+COUNTIFS('Master Sheet'!S2:S6257,"ET-Capex") -> 194 | L34: =K34/SUM(K31:K35) -> 0.03101023
B35: Nokia/Ericsson | C35: =COUNTIFS('Master Sheet'!P2:P6257,"Nokia/Ericsson") -> 374 | D35: =C35/SUM(C31:C36) -> 0.059782609 | J35: Other (RDU, Pole, etc.) | K35: =B5-SUM(K31:K34) -> 285 | L35: =K35/SUM(K31:K35) -> 0.045556266
B36: Other | C36: =B5-SUM(C31:C35) -> 149 | D36: =C36/SUM(C31:C36) -> 0.023817136
B38: Data Source: GIS Master Site Database | Report Date: January 2024 | Confidential

Sheet Master Sheet
A1: Sitecode | B1: Key | C1: Region | D1: 2G logical ID | E1: 3G logical ID | F1: 4G logical ID | G1: 5G Logical ID | H1: 2G Site Status | I1: 3G Site Status | J1: 4G Site Status | K1: 5G Status | L1: 3G Scope | M1: Purpose | N1: Latitude | O1: Longitude | P1: Vendor | Q1: Site Type-1 | R1: Passive Structure - Sharing Vs Non Sharing | S1: Site Type | T1: Structure Owner | U1: Sharing Model | V1: Site Model | W1: Technology | X1: Cabinet Type | Y1: 2CC/3CC | Z1: 4T4R | AA1: 3G Configuration | AB1: LTE Configuration | AC1: 5G Configuration (ICC/2CC/3CC) | AD1: Zone ID | AE1: Antenna Height | AF1: Count of 3G/4G RRU | AG1: Count of 5G RRU | AH1: 5G Band Information (N41/N78/N41+N78) | AI1: Count of SRAN Antennas | AJ1: Count of 5G Antennas | AK1: Splitter(Y/N) | AL1: Scope | AM1: CW PO | AN1: CW contractor | AO1: Plot Size | AP1: Structure Type | AQ1: Structure Supplier | AR1: Equipment Room Type | AS1: CW Status | AT1: Power source | AU1: Power Status | AV1: 2G Status | AY1: 3G 2100 Status | BB1: 3G 900 Status | BE1: 4G 800 Status | BH1: 4G 1800 Status | BK1: Transmission Media | BL1: Number of MW dishes on site | BM1: Configuration | BQ1: Antenna Type 1 | BR1: Antenna Type 2 | BS1: Antenna Type 3 | BT1: Antenna Type 4 | BU1: Antenna Type 5 | BV1: Antenna Type 6 | BW1: Feeder type | BX1: MW 1 | BY1: MW 2 | BZ1: MW 3 | CA1: MW 4 | CB1: MW 5 | CC1: MW 6 | CD1: TRS Media | CE1: Device Name | CF1: Height | CG1: Structure Type | CH1: Remarks
A2: AAC4348 | B2: Site 5916 | C2: AAN | D2: AAC4348 | E2: AAC4348 | F2: AAC4348 | G2: AACNR4348 | H2: On Air | I2: On Air | J2: On Air | K2: On Air | L2: 2009 | M2: Permanent | N2: 24.18311 | O2: 55.32005 | P2: Nokia/Ericsson | Q2: Outdoor | R2: EITC Passive Infrastructure | S2: Greenfield | T2: Outdoor Green field-du Owned | U2: Du Solo | V2: RDU | W2: 2G+3G+4G+5G | X2: Enclosure6130 | Y2: 4CC | Z2: 4T4R | AA2: U2100 + U900 | AB2: L1800 (F1+F2) + L800 + L2100 | AC2: 1CC | AD2: 8007100 | AE2: 28 | AF2: 5 | AG2: 3 | AH2: N41 | AI2: 3 | AJ2: 3 | CD2: IIB | CE2: AAC-4348-CSG-IXR-E-1 | CF2: 30 | CG2: #N/A | CH2: from data base
A3: AAG6066 | B3: Site 5917 | C3: AAN | E3: AAG6066 | F3: AAG6066 | G3: AAGNR6066 | I3: On Air | J3: On Air | K3: On Air | L3: 42208 | M3: Permanent | N3: 24.08449 | O3: 55.71706 | P3: Ericsson | Q3: Outdoor | R3: EITC Passive Infrastructure | S3: Greenfield | T3: Outdoor Green field-du Owned | U3: Du Solo | V3: RDU | W3: 3G+4G+5G | X3: Enclosure6130 | Y3: 2CC | Z3: 4T4R | AA3: U2100 + U900 | AB3: L800 + L2100 | AC3: 1CC | AD3: 8002800 | AE3: 30 | AF3: 6 | AG3: 3 | AH3: N41 | AI3: 3 | AJ3: 3 | CD3: IIB | CE3: AAG-6066-CSG-IXR-E-1 | CF3: 30 | CG3: #N/A | CH3: from data base
A4: AAG6068 | B4: Site 5918 | C4: AAN | D4: AAG6068 | E4: AAG6068 | F4: AAG6068 | G4: AAGNR6068 | H4: On Air | I4: On Air | J4: On Air | K4: On Air | L4: 42312 | M4: Permanent | N4: 24.06131 | O4: 55.72543 | P4: Nokia/Ericsson | Q4: Outdoor | R4: EITC Passive Infrastructure | S4: Greenfield | T4: Outdoor Green field-du Owned | U4: Du Solo | V4: RDU | W4: 2G+3G+4G+5G | X4: Enclosure6130 | Y4: 3CC | Z4: 4T4R | AA4: U2100 + U900 | AB4: L1800 (F1) + L800 + L2100 | AC4: 2CC | AD4: 8002800 | AE4: 29 | AF4: 6 | AG4: 3 | AH4: N78 | AI4: 3 | AJ4: 3 | CD4: IIB | CE4: AAG-6068-CSG-IXR-E-1 | CF4: 30 | CG4: #N/A | CH4: from data base
A5: AAG6096 | B5: Site 5919 | C5: AAN | E5: AAG6096 | F5: AAG6096 | G5: AAGNR6096 | I5: On Air | J5: On Air | K5: On Air | L5: 2009 | M5: Permanent | N5: 24.232414 | O5: 55.761819 | P5: Ericsson | Q5: Outdoor | R5: EITC Passive Infrastructure | S5: Greenfield | T5: Outdoor Green field-du Owned- Light Pole | U5: Du Solo | V5: Mini-Tower | W5: 3G+4G+5G | X5: Enclosure6130 | Y5: 2CC | Z5: 4T4R | AA5: U2100 + U900 | AB5: L1800 (F1) + L2100 | AC5: 2CC | AD5: 8001800 | AE5: 15 | AF5: 5 | AG5: 3 | AH5: N78 | AI5: 3 | AJ5: 3 | CD5: IIB | CE5: AAG-6096-CSG-IXR-E-1
A6: AAG6105 | B6: Site 5920 | C6: AAN | E6: AAG6105 | F6: AAG6105 | I6: On Air | J6: On Air | L6: 2023 | M6: Temporary | N6: 24.301 | O6: 55.12645 | P6: Ericsson | Q6: Outdoor | R6: EITC Passive Infrastructure | S6: Greenfield | T6: Outdoor Green field-du Owned | V6: Monopole | W6: 3G+4G | X6: Enclosure6130 | Y6: 4CC | Z6: 4T4R | AA6: U2100 + U900 | AB6: L1800 (F1+F2) + L800 + L2100 | AD6: 8005700 | AE6: 30 | AF6: 6 | AI6: 3 | CD6: MW | CE6: 0
A7: AAG6032 | B7: Site 5921 | C7: AAN | E7: AAG6032 | F7: AAGL6032 | G7: AAGNR6032 | I7: On Air | J7: On Air | K7: On Air | L7: 42149 | M7: Permanent | N7: 24.24575 | O7: 55.71282 | P7: Nokia/Ericsson | Q7: Outdoor | R7: EITC Passive Infrastructure | S7: Greenfield | T7: Outdoor Green field-du Owned | U7: Du Solo | V7: RDU | W7: 3G+4G+5G | X7: BTS3900 | Y7: 3CC | Z7: 4T4R | AA7: U2100 + U900 | AB7: L1800 (F1) + L800 + L2100 | AC7: 2CC | AD7: 8000600 | AE7: 28 | AF7: 8 | AG7: 3 | AH7: N78 | AI7: 4 | AJ7: 3 | CD7: IIB | CE7: AAG-6032-CSG-IXR-E-1 | CF7: 30 | CG7: #N/A | CH7: from data base
A8: AAN2005 | B8: Site 5922 | C8: AAN | D8: AAN2005 | E8: AAN2005 | F8: AAN2005 | G8: AANNR2005 | H8: On Air | I8: On Air | J8: On Air | K8: On Air | L8: 2009 | M8: Permanent | N8: 24.1709 | O8: 55.711 | P8: Nokia/Ericsson | Q8: Outdoor | R8: EITC Passive Infrastructure | S8: Greenfield | T8: Outdoor Green field-du Owned | U8: DU Solo | V8: Monopole | W8: 2G+3G+4G+5G | X8: Enclosure6130 | Y8: 4CC | Z8: 4T4R | AA8: U2100 + U900 | AB8: L1800 (F1+F2) + L800 + L2100 | AC8: 2CC | AD8: 8002500 | AE8: 28 | AF8: 6 | AG8: 3 | AH8: N78 | AI8: 3 | AJ8: 3 | CD8: IIB | CE8: AAN-2005-PREAGG-SR7-1 | CF8: 30 | CG8: #N/A | CH8: from data base
A9: AAN2006 | B9: Site 5923 | C9: AAN | D9: AAN2006 | E9: AAN2006 | F9: AAN2006 | G9: AANNR2006 | H9: Locked | I9: On Air | J9: On Air | K9: On Air | L9: 2009 | M9: Permanent | N9: 24.18795 | O9: 55.719 | P9: Nokia/Ericsson | Q9: Outdoor | R9: EITC Passive Infrastructure | S9: Greenfield | T9: Outdoor Green field-du Owned | U9: Du Solo | V9: Monopole | W9: 2G+3G+4G+5G | X9: Enclosure6130 | Y9: 3CC | Z9: 4T4R | AA9: U2100 + U900 | AB9: L1800 (F1) + L800 + L2100 | AC9: 2CC | AD9: 8002500 | AE9: 28 | AF9: 6 | AG9: 3 | AH9: N78 | AI9: 3 | AJ9: 3 | CD9: IIB | CE9: AAN-2006-PREAGG-SR7-1 | CF9: 30 | CG9: #N/A | CH9: from data base
A10: AAN2009 | B10: Site 5924 | C10: AAN | D10: AAN2009 | E10: AAN2009 | F10: AAN2009 | G10: AANNR2009 | H10: On Air | I10: On Air | J10: On Air | K10: On Air | L10: 2009 | M10: Permanent | N10: 24.1461 | O10: 55.6898 | P10: Nokia/Ericsson | Q10: Outdoor | R10: EITC Passive Infrastructure | S10: Greenfield | T10: Outdoor Green field-du Owned | U10: Du Solo | V10: Monopole | W10: 2G+3G+4G+5G | X10: Enclosure6130 | Y10: 4CC | Z10: 4T4R | AA10: U2100 + U900 | AB10: L1800 (F1+F2) + L800 + L2100 | AC10: 2CC | AD10: 8002900 | AE10: 30 | AF10: 6 | AG10: 3 | AH10: N78 | AI10: 3 | AJ10: 3 | CD10: IIB | CE10: AAN-2009-PREAGG-SR7-1 | CF10: 30 | CG10: #N/A | CH10: from data base
A11: AAN2012 | B11: Site 5925 | C11: AAN | D11: AAN2012 | E11: AAN2012 | F11: AAN2012 | G11: AANNR2012 | H11: On Air | I11: On Air | J11: On Air | K11: On Air | L11: 2009 | M11: Permanent | N11: 24.194599 | O11: 55.791079 | P11: Nokia/Ericsson | Q11: Outdoor | R11: EITC Passive Infrastructure | S11: Greenfield | T11: Outdoor Green field-du Owned | U11: Du Solo | V11: Monopole | W11: 2G+3G+4G+5G | X11: Enclosure6130 | Y11: 4CC | Z11: 4T4R | AA11: U2100 + U900 | AB11: L1800 (F1+F2) + L800 + L2100 | AC11: 2CC | AD11: 8001900 | AE11: 28 | AF11: 6 | AG11: 3 | AH11: N78 | AI11: 3 | AJ11: 3 | CD11: IIB | CE11: AAN-2012-CSG-SAR-X-1 | CF11: 30 | CG11: #N/A | CH11: from data base
A12: AAN2015 | B12: Site 5926 | C12: AAN | D12: AAN2015 | E12: AAN2015 | F12: AAN2015 | G12: AANNR2015 | H12: On Air | I12: On Air | J12: On Air | K12: On Air | L12: 2009 | M12: Permanent | N12: 24.18098 | O12: 55.75854 | P12: Nokia/Ericsson | Q12: Outdoor | R12: EITC Passive Infrastructure | S12: Greenfield | T12: Outdoor Green field-du Owned | U12: Du Solo | V12: Monopole | W12: 2G+3G+4G+5G | X12: Enclosure6130 | Y12: 4CC | Z12: 4T4R | AA12: U2100 + U900 | AB12: L1800 (F1+F2) + L800 + L2100 | AC12: 2CC | AD12: 8002400 | AE12: 30 | AF12: 6 | AG12: 3 | AH12: N78 | AI12: 3 | AJ12: 3 | CD12: IIB | CE12: AAN-2015-CSG-SAR-X-1 | CF12: 30 | CG12: #N/A | CH12: from data base
A13: AAN2018 | B13: Site 5927 | C13: AAN | D13: AAN2018 | E13: AAN2018 | F13: AAN2018 | G13: AANNR2018 | H13: On Air | I13: On Air | J13: On Air | K13: On Air | L13: 2009 | M13: Permanent | N13: 24.200853 | O13: 55.746255 | P13: Nokia/Ericsson | Q13: Outdoor | R13: EITC Passive Infrastructure | S13: Greenfield | T13: Outdoor Green field-du Owned | U13: DU Solo | V13: Lattice Tower | W13: 2G+3G+4G+5G | X13: Enclosure6130 | Y13: 3CC | Z13: 4T4R | AA13: U2100 + U900 | AB13: L1800 (F1) + L800 + L2100 | AC13: 2CC | AD13: 8002400 | AE13: 33 | AF13: 6 | AG13: 3 | AH13: N78 | AI13: 3 | AJ13: 3 | CD13: IIB | CE13: AAN-2018-CSG-IXR-E-1 | CF13: 30 | CG13: #N/A | CH13: from data base
A14: AAN2028 | B14: Site 5928 | C14: AAN | D14: AAN2028 | E14: AAN2028 | F14: AAN2028 | G14: AANNR2028 | H14: On Air | I14: On Air | J14: On Air | K14: On Air | L14: 2009 | M14: Permanent | N14: 24.1504 | O14: 55.64811 | P14: Nokia/Ericsson | Q14: Outdoor | R14: EITC Passive Infrastructure | S14: Greenfield | T14: Outdoor Green field-du Owned | U14: Du Solo | V14: Monopole | W14: 2G+3G+4G+5G | X14: Enclosure6130 | Y14: 3CC | Z14: 4T4R | AA14: U2100 + U900 | AB14: L1800 (F1) + L800 + L2100 | AC14: 1CC | AD14: 8003100 | AE14: 27 | AF14: 6 | AG14: 3 | AH14: N41 | AI14: 3 | AJ14: 3 | CD14: IIB | CE14: AAN-2028-CSG-ASR920-LD-1 | CF14: 30 | CG14: #N/A | CH14: from data base
A15: AAN2029 | B15: Site 5929 | C15: AAN | D15: AAN2029 | E15: AAN2029 | F15: AAN2029 | G15: AANNR2029 | H15: On Air | I15: On Air | J15: On Air | K15: On Air | L15: 40488 | M15: Permanent | N15: 24.103425 | O15: 55.588392 | P15: Nokia/Ericsson | Q15: Outdoor | R15: EITC Passive Infrastructure | S15: Greenfield | T15: Outdoor Green field-du Owned | U15: Du Solo | V15: Lattice Tower | W15: 2G+3G+4G+5G | X15: Enclosure6130 | Y15: 2CC | Z15: 4T4R | AA15: U2100 + U900 | AB15: L800 + L2100 | AC15: 1CC | AD15: 8006400 | AE15: 40 | AF15: 6 | AG15: 3 | AH15: N41 | AI15: 3 | AJ15: 3 | CD15: IIB | CE15: AAN-2029-CSG-IXR-E-1 | CF15: 40 | CG15: #N/A | CH15: from data base
A16: AAN2053 | B16: Site 5930 | C16: AAN | D16: AAN2053 | E16: AAN2053 | F16: AAN2053 | G16: AANNR2053 | H16: On Air | I16: On Air | J16: On Air | K16: On Air | L16: 2009 | M16: Permanent | N16: 24.21676 | O16: 55.48553 | P16: Nokia/Ericsson | Q16: Outdoor | R16: EITC Passive Infrastructure | S16: Greenfield | T16: Outdoor Green field-du Owned | U16: Du Solo | V16: Lattice Tower | W16: 2G+3G+4G+5G | X16: Enclosure6130 | Y16: 2CC | Z16: 4T4R | AA16: U2100 + U900 | AB16: L800 + L2100 | AC16: 1CC | AD16: 8006700 | AE16: 47 | AF16: 8 | AG16: 3 | AH16: N41 | AI16: 4 | AJ16: 3 | AK16: Y | CD16: IIB | CE16: AAN-5002-AGGR-SR12-1 + AAN-5002-AGGR-SR12-2 + + + + | CF16: 35 | CG16: #N/A | CH16: from data base
A17: AAN2054 | B17: Site 5931 | C17: AAN | D17: AAN2054 | E17: AAN2054 | F17: AAN2054 | G17: AANNR2054 | H17: On Air | I17: On Air | J17: On Air | K17: On Air | L17: 2009 | M17: Permanent | N17: 24.164645 | O17: 55.263916 | P17: Nokia/Ericsson | Q17: Outdoor | R17: EITC Passive Infrastructure | S17: Greenfield | T17: Outdoor Green field-du Owned | U17: Du Solo | V17: Lattice Tower | W17: 2G+3G+4G+5G | X17: Enclosure6130 | Y17: 2CC | Z17: 4T4R | AA17: U2100 + U900 | AB17: L800 + L2100 | AC17: 1CC | AD17: 8007100 | AE17: 37 | AF17: 6 | AG17: 3 | AH17: N41 | AI17: 3 | AJ17: 3 | CD17: IIB | CE17: AAN-2054-CSG-IXR-E-1 | CF17: 50 | CG17: #N/A | CH17: from data base
A18: AAN2062 | B18: Site 5932 | C18: AAN | D18: AAN2062 | E18: AAN2062 | F18: AAN2062 | G18: AANNR2062 | H18: On Air | I18: On Air | J18: On Air | K18: On Air | L18: 2009 | M18: Permanent | N18: 24.195953 | O18: 55.752132 | P18: Nokia/Ericsson | Q18: Outdoor | R18: EITC Passive Infrastructure | S18: Greenfield | T18: Outdoor Green field-du Owned | U18: Du Solo | V18: Monopole | W18: 2G+3G+4G+5G | X18: Enclosure6130 | Y18: 4CC | Z18: 4T4R | AA18: U2100 + U900 | AB18: L1800 (F1+F2) + L800 + L2100 | AC18: 2CC | AD18: 8002400 | AE18: 27 | AF18: 6 | AG18: 3 | AH18: N78 | AI18: 3 | AJ18: 3 | CD18: IIB | CE18: AAN-2062-CSG-SAR-X-1 | CF18: 30 | CG18: #N/A | CH18: from data base
A19: AAN2069 | B19: Site 5933 | C19: AAN | D19: AAN2069 | E19: AAN2069 | F19: AAN2069 | G19: AANNR2069 | H19: On Air | I19: On Air | J19: On Air | K19: On Air | L19: 2009 | M19: Permanent | N19: 24.137198 | O19: 55.707023 | P19: Nokia/Ericsson | Q19: Outdoor | R19: EITC Passive Infrastructure | S19: Greenfield | T19: Outdoor Green field-du Owned | U19: Du Solo | V19: Monopole | W19: 2G+3G+4G+5G | X19: Enclosure6130 | Y19: 4CC | Z19: 4T4R | AA19: U2100 + U900 | AB19: L1800 (F1+F2) + L800 + L2100 | AC19: 2CC | AD19: 8002900 | AE19: 27 | AF19: 8 | AG19: 3 | AH19: N78 | AI19: 4 | AJ19: 3 | CD19: IIB | CE19: AAN-2069-CSG-IXR-E-1 | CF19: 30 | CG19: #N/A | CH19: from data base
A20: AAN2071 | B20: Site 5934 | C20: AAN | D20: AAN2071 | E20: AAN2071 | F20: AAN2071 | G20: AANNR2071 | H20: On Air | I20: On Air | J20: On Air | K20: On Air | L20: 2009 | M20: Permanent | N20: 24.1917 | O20: 55.53539 | P20: Nokia/Ericsson | Q20: Outdoor | R20: EITC Passive Infrastructure | S20: Greenfield | T20: Outdoor Green field-du Owned | U20: Du Solo | V20: Monopole | W20: 2G+3G+4G+5G | X20: Enclosure6130 | Y20: 3CC | Z20: 4T4R | AA20: U2100 + U900 | AB20: L1800 (F1) + L800 + L2100 | AC20: 1CC | AD20: 8006500 | AE20: 25 | AF20: 6 | AG20: 3 | AH20: N41 | AI20: 3 | AJ20: 3 | CD20: OSN/IIB | CE20: AAN-2071-CSG-SAR-8-1 | CF20: 30 | CG20: #N/A | CH20: from data base
A21: AAN2072 | B21: Site 5935 | C21: AAN | D21: AAN2072 | E21: AAN2072 | F21: AAN2072 | G21: AANNR2072 | H21: On Air | I21: On Air | J21: On Air | K21: On Air | L21: 2009 | M21: Permanent | N21: 24.12178 | O21: 55.71353 | P21: Nokia/Ericsson | Q21: Outdoor | R21: EITC Passive Infrastructure | S21: Greenfield | T21: Outdoor Green field-du Owned | U21: Du Solo | V21: Monopole | W21: 2G+3G+4G+5G | X21: Enclosure6130 | Y21: 3CC | Z21: 4T4R | AA21: U2100 + U900 | AB21: L1800 (F1) + L800 + L2100 | AC21: 2CC | AD21: 8003300 | AE21: 26 | AF21: 6 | AG21: 3 | AH21: N78 | AI21: 3 | AJ21: 3 | CD21: IIB | CE21: AAN-2072-CSG-ASR920-LD-1 | CF21: 30 | CG21: #N/A | CH21: from data base
A22: AAN2073 | B22: Site 5936 | C22: AAN | D22: AAN2073 | E22: AAN2073 | F22: AAN2073 | G22: AANNR2073 | H22: On Air | I22: On Air | J22: On Air | K22: On Air | L22: 40477 | M22: Permanent | N22: 24.076633 | O22: 55.662002 | P22: Nokia/Ericsson | Q22: Outdoor | R22: EITC Passive Infrastructure | S22: Greenfield | T22: Outdoor Green field-du Owned | U22: Du Solo | V22: Monopole | W22: 2G+3G+4G+5G | X22: Enclosure6130 | Y22: 4CC | Z22: 4T4R | AA22: U2100 + U900 | AB22: L1800 (F1+F2) + L800 + L2100 | AC22: 1CC | AD22: 8006600 | AE22: 28 | AF22: 6 | AG22: 3 | AH22: N41 | AI22: 3 | AJ22: 3 | CD22: IIB | CE22: AAN-2073-CSG-IXR-E-1 | CF22: 30 | CG22: #N/A | CH22: from data base
A23: AAN2075 | B23: Site 5937 | C23: AAN | D23: AAN2075 | E23: AAN2075 | F23: AAN2075 | G23: AANNR2075 | H23: On Air | I23: On Air | J23: On Air | K23: On Air | L23: 2009 | M23: Permanent | N23: 24.149633 | O23: 55.738002 | P23: Nokia/Ericsson | Q23: Outdoor | R23: EITC Passive Infrastructure | S23: Greenfield | T23: Outdoor Green field-du Owned | U23: Du Solo | V23: Monopole | W23: 2G+3G+4G+5G | X23: Enclosure6130 | Y23: 3CC | Z23: 4T4R | AA23: U2100 + U900 | AB23: L1800 (F1) + L800 + L2100 | AC23: 2CC | AD23: 8002400 | AE23: 28 | AF23: 6 | AG23: 3 | AH23: N78 | AI23: 3 | AJ23: 3 | CD23: IIB | CE23: AAN-2075-CSG-ASR920-LD-1 | CF23: 30 | CG23: #N/A | CH23: from data base
A24: AAN2077 | B24: Site 5938 | C24: AAN | D24: AAN2077 | E24: AAN2077 | F24: AAN2077 | G24: AANNR2077 | H24: On Air | I24: On Air | J24: On Air | K24: On Air | L24: 2009 | M24: Permanent | N24: 24.17965 | O24: 55.742905 | P24: Nokia/Ericsson | Q24: Outdoor | R24: EITC Passive Infrastructure | S24: Greenfield | T24: Outdoor Green field-du Owned | U24: Du Solo | V24: Monopole | W24: 2G+3G+4G+5G | X24: Enclosure6130 | Y24: 3CC | Z24: 4T4R | AA24: U2100 + U900 | AB24: L1800 (F1) + L800 + L2100 | AC24: 2CC | AD24: 8002600 | AE24: 26 | AF24: 6 | AG24: 3 | AH24: N78 | AI24: 3 | AJ24: 3 | CD24: MW | CE24: 0 | CF24: 30 | CG24: #N/A | CH24: from data base
A25: AAN2080 | B25: Site 5939 | C25: AAN | D25: AAN2080 | E25: AAN2080 | F25: AAN2080 | G25: AANNR2080 | H25: On Air | I25: On Air | J25: On Air | K25: On Air | L25: 2009 | M25: Permanent | N25: 24.17916 | O25: 55.77082 | P25: Nokia/Ericsson | Q25: Outdoor | R25: EITC Passive Infrastructure | S25: Greenfield | T25: Outdoor Green field-du Owned | U25: Du Solo | V25: Lattice Tower | W25: 2G+3G+4G+5G | X25: Enclosure6130 | Y25: 4CC | Z25: 4T4R | AA25: U2100 + U900 | AB25: L1800 (F1+F2) + L800 + L2100 | AC25: 2CC | AD25: 8002400 | AE25: 38 | AF25: 6 | AG25: 3 | AH25: N78 | AI25: 3 | AJ25: 3 | CD25: IIB | CE25: AAN-2080-CSG-ASR920-LD-1 | CF25: 40 | CG25: #N/A | CH25: from data base
A26: AAN2084 | B26: Site 5940 | C26: AAN | D26: AAN2084 | E26: AAN2084 | F26: AAN2084 | G26: AANNR2084 | H26: On Air | I26: On Air | J26: On Air | K26: On Air | L26: 2009 | M26: Permanent | N26: 24.17228 | O26: 55.67493 | P26: Nokia/Ericsson | Q26: Outdoor | R26: EITC Passive Infrastructure | S26: Greenfield | T26: Outdoor Green field-du Owned | U26: Du Solo | V26: Monopole | W26: 2G+3G+4G+5G | X26: Enclosure6130 | Y26: 3CC | Z26: 4T4R | AA26: U2100 + U900 | AB26: L1800 (F1) + L800 + L2100 | AC26: 2CC | AD26: 8003000 | AE26: 27 | AF26: 6 | AG26: 3 | AH26: N78 | AI26: 3 | AJ26: 3 | CD26: IIB | CE26: AAN-2084-CSG-SAR-X-1 | CF26: 30 | CG26: #N/A | CH26: from data base
A27: AAN2085 | B27: Site 5941 | C27: AAN | D27: AAN2085 | E27: AAN2085 | F27: AAN2085 | G27: AANNR2085 | H27: On Air | I27: On Air | J27: On Air | K27: On Air | L27: 2009 | M27: Permanent | N27: 24.1294 | O27: 55.682 | P27: Nokia/Ericsson | Q27: Outdoor | R27: EITC Passive Infrastructure | S27: Greenfield | T27: Outdoor Green field-du Owned | U27: Du Solo | V27: Monopole | W27: 2G+3G+4G+5G | X27: Enclosure6130 | Y27: 4CC | Z27: 4T4R | AA27: U2100 + U900 | AB27: L1800 (F1+F2) + L800 + L2100 | AC27: 2CC | AD27: 8002900 | AE27: 28 | AF27: 6 | AG27: 3 | AH27: N78 | AI27: 3 | AJ27: 3 | CD27: IIB | CE27: AAN-2085-CSG-SAR-X-1 | CF27: 30 | CG27: #N/A | CH27: from data base
A28: AAN2086 | B28: Site 5942 | C28: AAN | D28: AAN2086 | E28: AAN2086 | F28: AAN2086 | G28: AANNR2086 | H28: On Air | I28: On Air | J28: On Air | K28: On Air | L28: 2009 | M28: Permanent | N28: 24.19925 | O28: 55.43428 | P28: Nokia/Ericsson | Q28: Outdoor | R28: EITC Passive Infrastructure | S28: Greenfield | T28: Outdoor Green field-du Owned | U28: Du Solo | V28: Lattice Tower | W28: 2G+3G+4G+5G | X28: Enclosure6130 | Y28: 4CC | Z28: 4T4R | AA28: U2100 + U900 | AB28: L1800 (F1+F2) + L800 + L2100 | AC28: 1CC | AD28: 8006700 | AE28: 41 | AF28: 6 | AG28: 3 | AH28: N41 | AI28: 3 | AJ28: 3 | CD28: IIB | CE28: AAN-2086-CSG-ASR920-LD-1 | CF28: 40 | CG28: #N/A | CH28: from data base
A29: AAN2087 | B29: Site 5943 | C29: AAN | D29: AAN2087 | E29: AAN2087 | F29: AAN2087 | G29: AANNR2087 | H29: On Air | I29: On Air | J29: On Air | K29: On Air | L29: 2009 | M29: Permanent | N29: 24.202337 | O29: 55.731741 | P29: Nokia/Ericsson | Q29: Outdoor | R29: EITC Passive Infrastructure | S29: Greenfield | T29: Outdoor Green field-du Owned | U29: Du Solo | V29: Monopole | W29: 2G+3G+4G+5G | X29: Enclosure6130 | Y29: 3CC | Z29: 4T4R | AA29: U2100 + U900 | AB29: L1800 (F1) + L800 + L2100 | AC29: 2CC | AD29: 8002500 | AE29: 28 | AF29: 6 | AG29: 3 | AH29: N78 | AI29: 3 | AJ29: 3 | CD29: IIB | CE29: AAN-2087-CSG-IXR-E-1 | CF29: 30 | CG29: #N/A | CH29: from data base
A30: AAN2088 | B30: Site 5944 | C30: AAN | D30: AAN2088 | E30: AAN2088 | F30: AAN2088 | G30: AANNR2088 | H30: On Air | I30: On Air | J30: On Air | K30: On Air | L30: 2009 | M30: Permanent | N30: 24.1531 | O30: 55.81241 | P30: Nokia/Ericsson | Q30: Outdoor | R30: EITC Passive Infrastructure | S30: Greenfield | T30: Outdoor Green field-du Owned | U30: Du Solo | V30: Monopole | W30: 2G+3G+4G+5G | X30: Enclosure6130 | Y30: 4CC | Z30: 4T4R | AA30: U2100 + U900 | AB30: L1800 (F1+F2) + L800 + L2100 | AC30: 1CC | AD30: 8002200 | AE30: 27 | AF30: 6 | AG30: 3 | AH30: N41 | AI30: 3 | AJ30: 3 | CD30: IIB | CE30: AAN-2088-PREAGG-SR7-1 | CF30: 30 | CG30: #N/A | CH30: from data base
A31: AAN2096 | B31: Site 5945 | C31: AAN | D31: AAN2096 | E31: AAN2096 | F31: AAN2096 | G31: AANNR2096 | H31: On Air | I31: On Air | J31: On Air | K31: On Air | L31: 2009 | M31: Permanent | N31: 24.1674 | O31: 55.1179 | P31: Nokia/Ericsson | Q31: Outdoor | R31: EITC Passive Infrastructure | S31: Greenfield | T31: Outdoor Green field-du Owned | U31: Du Solo | V31: Lattice Tower | W31: 2G+3G+4G+5G | X31: Enclosure6130 | Y31: 4CC | Z31: 4T4R | AA31: U2100 + U900 | AB31: L1800 (F1+F2) + L800 + L2100 | AC31: 1CC | AD31: 8007300 | AE31: 40 | AF31: 8 | AG31: 3 | AH31: N41 | AI31: 4 | AJ31: 3 | CD31: IIB | CE31: AAN-2096-CSG-IXR-E-1 | CF31: 45 | CG31: #N/A | CH31: from data base
A32: AAN2098 | B32: Site 5946 | C32: AAN | D32: AAN2098 | E32: AAN2098 | F32: AAN2098 | G32: AANNR2098 | H32: On Air | I32: On Air | J32: On Air | K32: On Air | L32: 2009 | M32: Permanent | N32: 24.19101 | O32: 55.35354 | P32: Nokia/Ericsson | Q32: Outdoor | R32: EITC Passive Infrastructure | S32: Greenfield | T32: Outdoor Green field-du Owned | U32: Du Solo | V32: Lattice Tower | W32: 2G+3G+4G+5G | X32: Enclosure6130 | Y32: 4CC | Z32: 4T4R | AA32: U2100 + U900 | AB32: L1800 (F1+F2) + L800 + L2100 | AC32: 1CC | AD32: 8007100 | AE32: 43 | AF32: 6 | AG32: 3 | AH32: N41 | AI32: 3 | AJ32: 3 | CD32: OSN/IIB | CE32: AAN-2098-CSG-SAR-8-1 | CF32: 50 | CG32: #N/A | CH32: from data base
A33: AAN2200 | B33: Site 5947 | C33: AAN | E33: AAN2200 | F33: AAN2200 | G33: AANNR2200 | I33: On Air | J33: On Air | K33: On Air | L33: 42960 | M33: Permanent | N33: 23.630973 | O33: 55.561021 | P33: Ericsson | Q33: Outdoor | R33: EITC Passive Infrastructure | S33: Greenfield | T33: Outdoor Green field-du Owned | U33: Du Solo | V33: Monopole | W33: 3G+4G+5G | X33: Enclosure6130 | Y33: 2CC | Z33: 4T4R | AA33: U2100 + U900 | AB33: L800 + L2100 | AC33: 1CC | AD33: 8009300 | AE33: 33 | AF33: 6 | AG33: 3 | AH33: N41 | AI33: 3 | AJ33: 3 | CD33: MW | CE33: 0 | CF33: 35 | CG33: #N/A | CH33: from data base
A34: AAN2250 | B34: Site 5948 | C34: AAN | D34: AAN2250 | E34: AAN2250 | F34: AAN2250 | G34: AANNR2250 | H34: On Air | I34: On Air | J34: On Air | K34: On Air | L34: 2009 | M34: Permanent | N34: 24.18723 | O34: 55.73708 | P34: Nokia/Ericsson | Q34: Outdoor | R34: EITC Passive Infrastructure | S34: Greenfield | T34: Outdoor Green field-du Owned | U34: Du Solo | V34: Monopole | W34: 2G+3G+4G+5G | X34: Enclosure6130 | Y34: 3CC | Z34: 4T4R | AA34: U2100 + U900 | AB34: L1800 (F1) + L800 + L2100 | AC34: 2CC | AD34: 8002500 | AE34: 28 | AF34: 6 | AG34: 3 | AH34: N78 | AI34: 3 | AJ34: 3 | CD34: IIB | CE34: AAN-2250-CSG-ASR920-LD-1 | CF34: 30 | CG34: #N/A | CH34: from data base
A35: AAN2252 | B35: Site 5949 | C35: AAN | D35: AAN2252 | E35: AAN2252 | F35: AAN2252 | G35: AANNR2252 | H35: On Air | I35: On Air | J35: On Air | K35: On Air | L35: 2009 | M35: Permanent | N35: 24.18841 | O35: 55.76362 | P35: Nokia/Ericsson | Q35: Outdoor | R35: EITC Passive Infrastructure | S35: Greenfield | T35: Outdoor Green field-du Owned | U35: Du Solo | V35: Monopole | W35: 2G+3G+4G+5G | X35: Enclosure6130 | Y35: 4CC | Z35: 4T4R | AA35: U2100 + U900 | AB35: L1800 (F1+F2) + L800 + L2100 | AC35: 2CC | AD35: 8002400 | AE35: 28 | AF35: 6 | AG35: 3 | AH35: N78 | AI35: 3 | AJ35: 3 | CD35: IIB | CE35: AAN-2252-CSG-SAR-X-1 | CF35: 30 | CG35: #N/A | CH35: from data base
A36: AAN2253 | B36: Site 5950 | C36: AAN | E36: AAN2253 | F36: AAN2253 | G36: AANNR2253 | I36: On Air | J36: On Air | K36: On Air | L36: 2009 | M36: Permanent | N36: 24.22194 | O36: 55.74569 | P36: Ericsson | Q36: Outdoor | R36: Site Sharing | S36: Site Sharing | T36: Outdoor Site Sharing-Etisalat Owned | U36: SS Opex | V36: Site Share | W36: 3G+4G+5G | X36: Enclosure6130 | Y36: 4CC | Z36: 4T4R | AA36: U2100 + U900 | AB36: L1800 (F1+F2) + L800 + L2100 | AC36: 2CC | AD36: 8001500 | AE36: 19 | AF36: 6 | AG36: 3 | AH36: N78 | AI36: 3 | AJ36: 3 | CD36: IIB | CE36: AAN-2253-CSG-SAR-X-1 | CF36: 23 | CG36: PalmTree
A37: AAN2256 | B37: Site 5951 | C37: AAN | D37: AAN2256 | E37: AAN2256 | F37: AAN2256 | G37: AANNR2256 | H37: On Air | I37: On Air | J37: On Air | K37: On Air | L37: 2009 | M37: Permanent | N37: 24.1592 | O37: 55.69785 | P37: Nokia/Ericsson | Q37: Outdoor | R37: EITC Passive Infrastructure | S37: Greenfield | T37: Outdoor Green field-du Owned | U37: DU Solo | V37: Monopole | W37: 2G+3G+4G+5G | X37: Enclosure6130 | Y37: 4CC | Z37: 4T4R | AA37: U2100 + U900 | AB37: L1800 (F1+F2) + L800 + L2100 | AC37: 2CC | AD37: 8002900 | AE37: 26 | AF37: 8 | AG37: 3 | AH37: N78 | AI37: 4 | AJ37: 3 | CD37: IIB | CE37: AAN-2256-CSG-SAR-X-1 | CF37: 30 | CG37: #N/A | CH37: from data base
A38: AAN2262 | B38: Site 5952 | C38: AAN | D38: AAN2262 | E38: AAN2262 | F38: AAN2262 | G38: AANNR2262 | H38: On Air | I38: On Air | J38: On Air | K38: On Air | L38: 2009 | M38: Permanent | N38: 24.11309 | O38: 55.74963 | P38: Nokia/Ericsson | Q38: Outdoor | R38: Site Sharing | S38: Site Sharing | T38: Outdoor Site Sharing-Etisalat Owned | U38: SS Opex | V38: SS - Lattice Tower | W38: 2G+3G+4G+5G | X38: Enclosure6130 | Y38: 3CC | Z38: 4T4R | AA38: U2100 + U900 | AB38: L1800 (F1) + L800 + L2100 | AC38: 2CC | AD38: 8002700 | AE38: 35 | AF38: 6 | AG38: 3 | AH38: N78 | AI38: 3 | AJ38: 3 | CD38: IIB | CE38: AAN-2262-CSG-IXR-E-1 | CF38: 35 | CG38: Monopole | CH38: sharing site/ from data base
A39: AAN2263 | B39: Site 5953 | C39: AAN | D39: AAN2263 | E39: AAN2263 | F39: AAN2263 | H39: On Air | I39: On Air | J39: On Air | L39: 2009 | M39: Permanent | N39: 24.10437 | O39: 55.7408 | P39: Nokia/Ericsson | Q39: Outdoor | R39: Site Sharing | S39: Site Sharing | T39: Outdoor Site Sharing-Etisalat Owned | U39: SS Opex | V39: SS - Lattice Tower | W39: 2G+3G+4G | X39: Enclosure6130 | Y39: 3CC | Z39: 4T4R | AA39: U2100 + U900 | AB39: L1800 (F1) + L800 + L2100 | AD39: 8002700 | AE39: 25 | AF39: 6 | AI39: 3 | CD39: MW | CE39: 0 | CF39: 30 | CG39: Monopole | CH39: sharing site/ from data base
A40: AAN2264 | B40: Site 5954 | C40: AAN | D40: AAN2264 | E40: AAN2264 | F40: AAN2264 | G40: AANNR2264 | H40: On Air | I40: On Air | J40: On Air | K40: On Air | L40: 40523 | M40: Permanent | N40: 24.0582 | O40: 55.72555 | P40: Nokia/Ericsson | Q40: Outdoor | R40: EITC Passive Infrastructure | S40: Greenfield | T40: Outdoor Green field-du Owned | U40: Du Solo | V40: Lattice Tower | W40: 2G+3G+4G+5G | X40: Enclosure6130 | Y40: 3CC | Z40: 4T4R | AA40: U2100 + U900 | AB40: L1800 (F1) + L800 + L2100 | AC40: 2CC | AD40: 8002800 | AE40: 25 | AF40: 6 | AG40: 3 | AH40: N78 | AI40: 3 | AJ40: 3 | CD40: IIB | CE40: AAN-2264-CSG-IXR-E-1 | CF40: 45 | CG40: #N/A | CH40: from data base
...

Sheet Dismantled Sites
A1: Sitecode | B1: Region | C1: 2G logical ID | D1: 3G logical ID | E1: 4G logical ID | F1: 5G NRogicaNR ID | G1: 2G Site Status | H1: 3G Site Status | I1: 4G Site Status | J1: 5G Status | K1: Date of Dismantle | L1: Replacment site ID ( If Any)
A2: AUH2671 | B2: AUH | C2: AUH2671 | D2: AUH2671 | G2: Dismantled | H2: Dismantled | I2: Dismantled | K2: 44229 | L2: AUH3403
A3: AUH2033 | B3: AUH | C3: AUH2033 | D3: AUH2033 | E3: AUHL2033 | F3: AUHNR2033 | G3: On Air | H3: Locked | I3: Locked | J3: On-Air | K3: 44229
A4: DXB2618 | B4: DXB | C4: DXB2618 | D4: DXB2618 | E4: DXBL2618 | G4: Dismantled | H4: Dismantled | I4: Dismantled | K4: 44355 | L4: DXB1433
A5: DXT1188 | B5: DXB | C5: DXT6188 | D5: DXT6188 | E5: DXTL1188 | G5: Dismantled | H5: Dismantled | I5: Dismantled | K5: 44144 | L5: DXB1810
A6: DXT1374 | B6: DXB | C6: DXB2374 | D6: DXB2374 | E6: DXTL1374 | G6: Dismantled | H6: Dismantled | I6: Dismantled | K6: 43901 | L6: DXB1374
A7: DXT1197 | B7: DXB | C7: DXT6197 | D7: DXT6197 | E7: DXTL1197 | G7: On Air | H7: On Air | I7: On Air | K7: 44386 | L7: DXB3087
A8: DXT1394 | B8: DXB | C8: DXT6394 | D8: DXT6394 | E8: DXTL1394 | G8: On Air | H8: On Air | I8: On Air | K8: 44167 | L8: DXV6319/ DXB2389
A9: DXT6514 | B9: DXB | C9: - | D9: DXT6514 | E9: DXTL6514 | G9: - | H9: On Air | I9: On Air | K9: - | L9: -
A10: DXB3544 | B10: DXB | C10: - | D10: DXB3544 | E10: DXBL3544 | G10: - | H10: On Air | I10: On Air | J10: On-Air | K10: 44363 | L10: -
A11: DXV6354 | B11: DXB | C11: - | D11: DXV6354 | E11: DXVL6354 | G11: - | H11: On Air | I11: On Air | K11: 44383 | L11: -
A12: AUH2671 | B12: AUH | C12: AUH2671 | D12: AUH2671 | G12: Dismantled | H12: Dismantled | I12: Dismantled | K12: 44229 | L12: AUH3403
A13: AUH2033 | B13: AUH | C13: AUH2033 | D13: AUH2033 | E13: AUHL2033 | F13: AUHNR2033 | G13: Dismantled | H13: Dismantled | I13: Dismantled | K13: 44355 | L13: AUH6614
A14: AUV6234 | B14: AUH | E14: AUVL6234 | I14: Dismantled | K14: 44441 | L14: RDV
A15: DXB2718 | B15: DXB | C15: DXB2718 | D15: DXB2718 | E15: DXBL2718 | G15: On Air | H15: On Air | I15: On Air | J15: On-Air | K15: 44396 | L15: DXB3788
A16: DXT1478 | B16: DXB | C16: DXB2478 | D16: DXB2478 | E16: DXTL1478 | G16: On Air | H16: Dismantled | I16: Dismantled | K16: 44239 | L16: DXB2631
A17: DXT6341 | B17: DXB | C17: DXT6341 | D17: DXT6341 | E17: DXTL6341 | G17: On Air | H17: Dismantled | I17: Dismantled | K17: 44364 | L17: -
A18: DXV6319 | B18: DXB | C18: - | D18: DXV6319 | E18: DXVL6319 | G18: - | H18: Dismantled | I18: Dismantled | K18: 44497 | L18: DXB2389
A19: DXV6240 | B19: DXB | C19: - | D19: DXV6240 | E19: DXVL6240 | G19: - | H19: Dismantled | I19: Dismantled | K19: 44442 | L19: DXB1893
A20: AUG6165 | B20: WR | C20: AUG6165 | D20: AUG6165 | E20: AUGL6165 | G20: Dismantled | H20: Dismantled | I20: D | K20: 44479 | L20: AUH2762
A21: AUG6057 | B21: AUH | D21: AUG6057 | E21: AUGL6057 | F21: AUGNR6057 | H21: Dismantled | I21: Dismantled | K21: 44493 | L21: AUH3406
A22: AUH2631 | B22: AUH | C22: AUH2631 | D22: AUH2631 | E22: AUHL2631 | G22: Dismantled | H22: Dismantled | I22: Dismantled | K22: 44517 | L22: AUH6118
A23: AUG4444 | B23: AUH | C23: AUG4444 | D23: AUG4444 | E23: AUGL4444 | F23: AUGNR4444 | G23: Dismantled | H23: Dismantled | I23: Dismantled | K23: 44545 | L23: AUH6590
A24: AUV6232 | B24: WR | D24: AUV6232 | E24: AUVL6232 | H24: Dismantled | I24: Dismantled | K24: 44523 | L24: AUH6578
A25: AUH3711 | B25: AUH | D25: AUH3711 | E25: AUHL3711 | H25: Dismantled | I25: Dismantled | K25: 44589 | L25: AUG6229
A26: DXB1176 | B26: DXB | C26: DXB1176 | D26: DXB1176 | E26: DXBL1176 | G26: Dismantled | H26: Dismantled | I26: Dismantled | J26: On-Air | K26: 44348 | L26: DXB2070
A27: DXT1424 | B27: DXB | C27: DXB2424 | D27: DXB2424 | E27: DXTL1424 | G27: Dismantled | H27: Dismantled | I27: Dismantled | J27: On-Air | K27: 44468 | L27: DXB2649
A28: DXT3196 | B28: DXB | C28: DXB2196 | D28: DXB2196 | E28: DXTL3196 | G28: Dismantled | H28: Dismantled | I28: Dismantled | K28: 44506 | L28: DXB2655
A29: DXV6542 | B29: DXB | C29: - | D29: DXV6542 | E29: DXVL6542 | G29: - | H29: Dismantled | I29: Dismantled | K29: 44525 | L29: DXB2649
A30: DXT3119 | B30: DXB | C30: DXT6119 | D30: DXT6119 | E30: DXTL3119 | G30: On Air | H30: On Air | I30: On Air | K30: 44545 | L30: DXB3748
A31: AUV6230 | B31: AUH | D31: AUV6230 | E31: AUVL6230 | H31: On Air | I31: On-Air | K31: 44594 | L31: AUH3581
A32: DXB3233 | B32: DXB | C32: DXB2233 | D32: DXB2233 | E32: DXBL3233 | F32: DXBNR3233 | G32: Dismantled | H32: Dismantled | I32: Dismantled | J32: Dismantled | K32: 44589 | L32: DXB3786
A33: DXV6401 | B33: DXB | C33: - | D33: DXV6401 | E33: DXVL6401 | G33: - | H33: Dismantled | I33: Dismantled | K33: 44600 | L33: DXB2452
A34: AUH3103 | B34: AUH | H34: Dismantled | I34: Dismantled
A35: DXB2104 | B35: DXB | C35: DXB2104 | D35: DXB2104 | E35: DXBL2104 | G35: On Air | H35: On Air | I35: On Air | K35: 44561 | L35: DXB2073
A36: DXB2939 | B36: DXB | C36: DXB2939 | D36: DXB2939 | E36: DXBL2939 | G36: On Air | H36: On Air | I36: On Air | K36: 44594 | L36: DXB2269
A37: DXT1405 | B37: DXB | C37: DXT6405 | D37: DXT6405 | E37: DXTL1405 | G37: On Air | H37: On Air | I37: On Air | K37: 44410 | L37: DXB3629
A38: DXB3920 | B38: DXB | C38: - | D38: DXB3920 | E38: DXBL3920 | G38: - | H38: On Air | I38: On Air | K38: 44210 | L38: -
A39: DXV6524 | B39: DXB | C39: - | D39: DXV6524 | E39: DXVL6524 | F39: DXVNR6524 | G39: - | H39: On Air | I39: On Air | J39: On-Air | K39: 44628 | L39: -
A40: DXV6494 | B40: DXB | C40: - | D40: DXV6494 | E40: DXVL6494 | G40: - | H40: On Air | I40: On Air | K40: 44628 | L40: -
...
