Workbook

Sheet summary
D3: Category | E3: Qty | F3: Estimated OSP Budget Requirements
D4: AUH Y2024 Fiber scope | E4: 622 | F4: 23.75M AED
D5: MW | E5: 1076
D6: other region | E6: 4
D7: Total | E7: =SUM(E4:E6) -> 1702

Sheet consdolidated (2)
L1: Total Required Budget | M1: =SUM(M3:M1906) -> 23933101
A3: IBS Ref. Code | B3: Sitecode | C3: Area | D3: Lat | E3: Long | F3: Site Type | G3: Scope | H3: Status | I3: Timeline | J3: EPOC | K3: Cost | L3: Depandancy | M3: Cost of Confirmed Fibe Sites | N3: Transport Feedback | P3: MW/CSG Plan statuw
B4: AAG6105 | C4: AUH | D4: 24.301 | E4: 55.12645 | F4: Existing | G4: OD | H4: Possible | I4: #N/A | J4: 0 | K4: 1168587 | N4: stay in MW
B5: AAN2200 | C5: AUH | D5: 23.630973 | E5: 55.561021 | F5: Existing | G5: OD | H5: Possible | I5: #N/A | J5: 0 | K5: 465948.03 | L5: Depend to Connect AAN2269 | N5: stay in MW
B6: AAN2263 | C6: AUH | D6: 24.10437 | E6: 55.7408 | F6: Existing | G6: OD | H6: Possible | I6: #N/A | J6: 0 | K6: 412056.04 | N6: stay in MW
B7: AAN2268 | C7: AUH | D7: 23.7534 | E7: 55.52595 | F7: Existing | G7: OD | H7: Possible | I7: #N/A | J7: 0 | K7: 1041620.8 | L7: Depend to Connect AAN3258 | N7: stay in MW
B8: AAN2269 | C8: AUH | D8: 23.63854 | E8: 55.56595 | F8: Existing | G8: OD | H8: Possible | I8: #N/A | J8: 0 | K8: 1227183.1 | L8: Depend to Connect AAN2421 | N8: stay in MW
B9: AAN2270 | C9: AUH | D9: 23.5403 | E9: 55.4962 | F9: Existing | G9: OD | H9: Possible | I9: #N/A | J9: 0 | K9: 1123293.8 | L9: Depend to Connect AAN2423 | N9: stay in MW
B10: AAN2271 | C10: AUH | D10: 23.39905 | E10: 55.42307 | F10: Existing | G10: OD | H10: Possible | I10: #N/A | J10: 0 | K10: 381278.82 | L10: Depend to Connect AAN2424 | N10: stay in MW
B11: AAN2272 | C11: AUH | D11: 23.3157 | E11: 55.35715 | F11: Existing | G11: OD | H11: Possible | I11: #N/A | J11: 0 | K11: 1410819.3 | L11: Depend to Connect AAN2425 | N11: stay in MW
B12: AAN2273 | C12: AUH | D12: 23.47247 | E12: 55.29668 | F12: Existing | G12: OD | H12: Possible | I12: #N/A | J12: 0 | K12: 1490477.4 | L12: Depend to Connect AAN2383 | N12: stay in MW
B13: AAN2312 | C13: AUH | D13: 24.1454 | E13: 55.5525 | F13: Existing | G13: OD | H13: Possible | I13: #N/A | J13: 0 | K13: 232515.62 | L13: Depend to Connect AAN3276 | N13: stay in MW
B14: AAN2314 | C14: AUH | D14: 24.17765 | E14: 55.46786 | F14: Existing | G14: OD | H14: Possible | I14: #N/A | J14: 0 | K14: 581935.88 | N14: stay in MW
B15: AAN2326 | C15: AUH | D15: 24.12057 | E15: 55.40578 | F15: Existing | G15: OD | H15: Possible | I15: #N/A | J15: 0 | K15: 710997.5 | L15: Depend to Connect AAN2588 | N15: stay in MW
B16: AAN2383 | C16: AUH | D16: 23.4285 | E16: 55.41047 | F16: Existing | G16: OD | H16: Possible | I16: #N/A | J16: 0 | K16: 1027449.9 | L16: Depend to Connect AAN3287 | N16: stay in MW
B17: AAN2393 | C17: AUH | D17: 24.09338 | E17: 55.10098 | F17: Existing | G17: OD | H17: Possible | I17: #N/A | J17: 0 | K17: 756039.55 | N17: stay in MW
B18: AAN2394 | C18: AUH | D18: 24.03036 | E18: 55.10789 | F18: Existing | G18: OD | H18: Possible | I18: #N/A | J18: 0 | K18: 1077294.8 | L18: Depend to Connect AAN2393 | N18: stay in MW
B19: AAN2396 | C19: AUH | D19: 23.98252 | E19: 55.18256 | F19: Existing | G19: OD | H19: Possible | I19: #N/A | J19: 0 | K19: 490163.46 | L19: Depend to Connect AAN3323 | N19: stay in MW
B20: AAN2398 | C20: AUH | D20: 24.00613 | E20: 55.40816 | F20: Existing | G20: OD | H20: Site survey required | I20: #N/A | J20: 0 | N20: stay in MW
B21: AAN2408 | C21: AUH | D21: 23.88059 | E21: 55.40385 | F21: Existing | G21: OD | H21: Possible | I21: #N/A | J21: 0 | K21: 974941.48 | N21: stay in MW
B22: AAN2421 | C22: AUH | D22: 23.70635 | E22: 55.56817 | F22: Existing | G22: OD | H22: Possible | I22: #N/A | J22: 0 | K22: 1377790.5 | L22: Depend to Connect AAN2268 | N22: stay in MW
B23: AAN2422 | C23: AUH | D23: 23.642853 | E23: 55.533472 | F23: Existing | G23: OD | H23: Possible | I23: #N/A | J23: 0 | K23: 328536.26 | L23: Depend to Connect AAN3396 | N23: stay in MW
B24: AAN2423 | C24: AUH | D24: 23.58869 | E24: 55.5346 | F24: Existing | G24: OD | H24: Possible | I24: #N/A | J24: 0 | K24: 854510.37 | L24: Depend to Connect AAN2200 | N24: stay in MW
B25: AAN2424 | C25: AUH | D25: 23.418382 | E25: 55.422881 | F25: Existing | G25: OD | H25: Possible | I25: #N/A | J25: 0 | K25: 411812.24 | L25: Depend to Connect AAN2424 | N25: stay in MW
B26: AAN2425 | C26: AUH | D26: 23.39908 | E26: 55.40094 | F26: Existing | G26: OD | H26: Possible | I26: #N/A | J26: 0 | K26: 381654.18 | L26: Depend to Connect AAN3231 | N26: stay in MW
B27: AAN2426 | C27: AUH | D27: 23.48755 | E27: 55.45717 | F27: Existing | G27: OD | H27: Possible | I27: #N/A | J27: 0 | K27: 1136245.7 | L27: Depend to Connect AAN2270 | N27: stay in MW
B28: AAN2427 | C28: AUH | D28: 23.63231 | E28: 55.55429 | F28: Existing | G28: OD | H28: Possible | I28: #N/A | J28: 0 | K28: 208440.37 | L28: Depend to Connect AAN2200 | N28: stay in MW
B29: AAN2429 | C29: AUH | D29: 24.03254 | E29: 55.65231 | F29: Existing | G29: OD | H29: Possible | I29: #N/A | J29: 0 | K29: 632676.75 | L29: Depend to Connect AAN3113 | N29: stay in MW
B30: AAN2436 | C30: AUH | D30: 24.21267 | E30: 55.95383 | F30: Existing | G30: OD | H30: Possible | I30: #N/A | J30: 0 | K30: 611344.25 | N30: stay in MW
B31: AAN2472 | C31: AUH | D31: 24.13992 | E31: 55.47881 | F31: Existing | G31: OD | H31: Possible | I31: #N/A | J31: 0 | K31: 808895.4 | L31: Depend to Connect AAN3280 | N31: stay in MW
B32: AAN2486 | C32: AUH | D32: 24.43684 | E32: 55.19456 | F32: Existing | G32: OD | H32: Possible | I32: #N/A | J32: 0 | K32: 999138.63 | N32: stay in MW
B33: AAN2490 | C33: AUH | D33: 24.5756 | E33: 55.34289 | F33: Existing | G33: OD | H33: Possible | I33: #N/A | J33: 0 | K33: 1418931.8 | N33: stay in MW
B34: AAN2504 | C34: AUH | D34: 23.58395 | E34: 55.45076 | F34: Existing | G34: OD | H34: Possible | I34: #N/A | J34: 0 | K34: 1101991.8 | L34: Depend to Connect AAN2270 | N34: stay in MW
B35: AAN2511 | C35: AUH | D35: 23.986718 | E35: 55.257541 | F35: Existing | G35: OD | H35: Possible | I35: #N/A | J35: 0 | K35: 1585477.6 | L35: Depend to Connect AAN3318 | N35: stay in MW
B36: AAN2513 | C36: AUH | D36: 24.59606 | E36: 55.39521 | F36: Existing | G36: OD | H36: Not possible | I36: #N/A | J36: 0 | K36: 0 | N36: stay in MW
B37: AAN2530 | C37: AUH | D37: 24.08954 | E37: 55.98216 | F37: Existing | G37: OD | H37: Possible | I37: #N/A | J37: 0 | K37: 696735.2 | N37: stay in MW
B38: AAN2849 | C38: AUH | D38: 23.41377 | E38: 55.40641 | F38: Existing | G38: OD | H38: Possible | I38: #N/A | J38: 0 | K38: 265715.09 | L38: Depend to Connect AAN2383 | N38: stay in MW
B39: AAN2871 | C39: AUH | D39: 24.17726 | E39: 55.73803 | F39: Existing | G39: OD | H39: Possible | I39: #N/A | J39: 0 | K39: 316791.19 | N39: stay in MW
B40: AAN2873 | C40: AUH | D40: 24.608564 | E40: 55.461224 | F40: Existing | G40: OD | H40: Possible | I40: #N/A | J40: 0 | K40: 732147.15 | L40: Depend to Connect AAN3134 | N40: stay in MW
B41: AAN2896 | C41: AUH | D41: 23.397574 | E41: 55.411981 | F41: Existing | G41: OD | H41: Possible | I41: #N/A | J41: 0 | K41: 205831.71 | L41: Depend to Connect AAN2425 | N41: stay in MW
...

Sheet Sheet2
A1: Site Code | B1: Latitude | C1: Longitude | D1: Region | E1: Site Type | F1: OSP Scope status | G1: OSP Status | H1: Cost | I1: Timeline | J1: Remarks | K1: Transport Feedback
A2: AAG6105 | B2: 24.301 | C2: 55.12645 | D2: AAN | E2: OD | F2: Not 2024 scope | K2: to be via MW
A3: AAN3376 | B3: 24.482847 | C3: 55.312434 | D3: AAN | E3: OD | F3: Not 2024 scope | G3: OSP ready | K3: existing fiber | L3: #N/A | M3: #N/A | N3: #N/A | O3: AAN3376
A4: AAN2944 | B4: 24.54658 | C4: 55.20779 | D4: AAN | E4: OD | F4: Not 2024 scope | K4: to be via MW
A5: AAN3314 | B5: 24.232158 | C5: 55.538544 | D5: AAN | E5: OD | F5: Not 2024 scope | G5: OSP ready
A6: AUG6244 | B6: 24.421783 | C6: 54.680092 | D6: AUH | E6: OD | F6: Y2024 scope | G6: Taawun | K6: Y2024 fiber scope
A7: AAN3562 | B7: 24.385085 | C7: 55.080896 | D7: AAN | E7: OD | F7: Not 2024 scope | K7: to be via MW
A8: AAN3621 | B8: 24.165144 | C8: 55.674168 | D8: AAN | E8: OD | F8: Not 2024 scope | G8: OSP ready
A9: AUH1332 | B9: 24.52436 | C9: 54.671444 | D9: AUH | E9: OD | F9: Not 2024 scope | G9: OSP ready
A10: AUH2016 | B10: 24.4328 | C10: 54.5029 | D10: AUH | E10: OD | F10: Not 2024 scope | K10: to be via MW
A11: AUH1338 | B11: 24.52294 | C11: 54.670598 | D11: AUH | E11: OD | F11: Not 2024 scope | G11: OSP ready
A12: AUH2244 | B12: 24.524151 | C12: 54.896038 | D12: AUH | E12: OD | F12: Not 2024 scope | G12: OSP ready
A13: AUH2250 | B13: 24.43895 | C13: 54.61713 | D13: AUH | E13: OD | F13: Y2024 scope | K13: Y2024 fiber scope
A14: AUH2139 | B14: 24.402359 | C14: 54.750036 | D14: AUH | E14: OD | F14: Not 2024 scope | G14: OSP ready
A15: AAN3586 | B15: 24.772756 | C15: 55.78012 | D15: AAN | E15: OD | F15: Not 2024 scope | K15: to be via MW
A16: AUH2429 | B16: 24.475705 | C16: 54.85195 | D16: AUH | E16: OD | F16: Not 2024 scope | G16: OSP Ready
A17: AUH2668 | B17: 24.34168 | C17: 54.50059 | D17: AUH | E17: OD | F17: Not 2024 scope | G17: OSP Ready under AUH2668
A18: AUH2443 | B18: 24.51324 | C18: 54.37183 | D18: AUH | E18: OD | F18: Y2024 scope | G18: Taawun | K18: Y2024 fiber scope
A19: AUH2496 | B19: 24.46796 | C19: 54.3794 | D19: AUH | E19: OD | F19: Not 2024 scope | G19: OSP ready
A20: AUH2716 | B20: 24.20244 | C20: 54.46275 | D20: AUH | E20: OD | F20: Not 2024 scope | G20: OSP ready
A21: AUH3031 | B21: 24.833996 | C21: 54.758568 | D21: AUH | E21: OD | F21: Not 2024 scope | K21: to be via MW
A22: AAN3536 | B22: 24.506082 | C22: 55.632166 | D22: AAN | E22: OD | F22: Not 2024 scope | G22: OSP ready
A23: AUH2821 | B23: 24.46147 | C23: 54.824555 | D23: AUH | E23: OD | F23: Not 2024 scope | G23: OSP ready
A24: AAN3578 | B24: 24.155369 | C24: 55.711152 | D24: AAN | E24: OD | F24: Not 2024 scope | G24: OSP ready
A25: AAN3607 | B25: 24.066224 | C25: 55.892893 | D25: AAN | E25: OD | F25: Not 2024 scope | G25: OSP ready
A26: AAN3579 | B26: 24.154937 | C26: 55.700203 | D26: AAN | E26: OD | F26: Not 2024 scope | G26: OSP ready
A27: AUH3072 | B27: 24.299067 | C27: 54.672818 | D27: AUH | E27: OD | F27: Y2024 scope | G27: Taawun | K27: Y2024 fiber scope
A28: AAN3613 | B28: 24.366577 | C28: 55.79303 | D28: AAN | E28: OD | F28: Not 2024 scope | G28: OSP ready
A29: AAN3545 | B29: 24.227858 | C29: 55.757993 | D29: AAN | E29: OD | F29: Not 2024 scope | G29: OSP ready
A30: AAN3573 | B30: 24.622802 | C30: 55.737799 | D30: AAN | E30: OD | F30: Not 2024 scope | K30: to be via MW
A31: AUH3040 | B31: 24.17001 | C31: 54.64447 | D31: AUH | E31: OD | F31: Not 2024 scope | G31: Possible | H31: 432951.7 | I31: 7 months | K31: existing fiber | L31: existing | M31: AUH3040 | N31: #N/A | O31: AUH3040
A32: AAN3549 | B32: 24.081033 | C32: 55.600666 | D32: AAN | E32: OD | F32: Not 2024 scope | G32: OSP ready
A33: AAN3531 | B33: 23.9613823 | C33: 55.0328846 | D33: AAN | E33: OD | F33: Not 2024 scope | K33: to be via MW
A34: AUH3350 | B34: 24.374456 | C34: 54.622955 | D34: AUH | E34: OD | F34: Not 2024 scope | G34: Taawun | K34: Y2024 fiber scope | M34: wala ito sa main list na nasa shared folder
A35: AAN3593 | B35: 24.217903 | C35: 55.795748 | D35: AAN | E35: OD | F35: Not 2024 scope | G35: OSP ready
A36: AUH3130 | B36: 24.3982 | C36: 54.5017 | D36: AUH | E36: OD | F36: Not 2024 scope | G36: OSP ready
A37: AAN3514 | B37: 24.201039 | C37: 55.797567 | D37: AAN | E37: OD | F37: Not 2024 scope | G37: OSP ready
A38: AAN3551 | B38: 24.313755 | C38: 55.803783 | D38: AAN | E38: OD | F38: Not 2024 scope | G38: OSP ready
A39: AUH3349 | B39: 24.38288 | C39: 54.61361 | D39: AUH | E39: OD | F39: Not 2024 scope | G39: Taawun | K39: Y2024 fiber scope
A40: AUH3388 | B40: 24.532192 | C40: 54.426428 | D40: AUH | E40: OD | F40: Not 2024 scope | K40: to be via MW
...

Sheet Sheet3
H3: AUH1332 | I3: =VLOOKUP(H3,Sheet2!$A:$F,6,0) -> Not 2024 scope | J3: =VLOOKUP(H3,Sheet2!$A:$G,7,0) -> OSP ready
H4: AUH1338 | I4: =VLOOKUP(H4,Sheet2!$A:$F,6,0) -> Not 2024 scope | J4: =VLOOKUP(H4,Sheet2!$A:$G,7,0) -> OSP ready
H5: AAN3607 | I5: =VLOOKUP(H5,Sheet2!$A:$F,6,0) -> Not 2024 scope | J5: =VLOOKUP(H5,Sheet2!$A:$G,7,0) -> OSP ready
H6: AAN3551 | I6: =VLOOKUP(H6,Sheet2!$A:$F,6,0) -> Not 2024 scope | J6: =VLOOKUP(H6,Sheet2!$A:$G,7,0) -> OSP ready
H7: AUH3926 | I7: =VLOOKUP(H7,Sheet2!$A:$F,6,0) -> Not 2024 scope | J7: =VLOOKUP(H7,Sheet2!$A:$G,7,0) -> OSP ready
H8: AUH2787 | I8: =VLOOKUP(H8,Sheet2!$A:$F,6,0) -> Not 2024 scope | J8: =VLOOKUP(H8,Sheet2!$A:$G,7,0) -> OSP ready
H9: AUH6615 | I9: =VLOOKUP(H9,Sheet2!$A:$F,6,0) -> Not 2024 scope | J9: =VLOOKUP(H9,Sheet2!$A:$G,7,0) -> OSP ready
H10: AUH3167 | I10: =VLOOKUP(H10,Sheet2!$A:$F,6,0) -> Not 2024 scope | J10: =VLOOKUP(H10,Sheet2!$A:$G,7,0) -> OSP ready
H11: AUH3909 | I11: =VLOOKUP(H11,Sheet2!$A:$F,6,0) -> Not 2024 scope | J11: =VLOOKUP(H11,Sheet2!$A:$G,7,0) -> OSP ready
H12: AUH3937 | I12: =VLOOKUP(H12,Sheet2!$A:$F,6,0) -> Not 2024 scope | J12: =VLOOKUP(H12,Sheet2!$A:$G,7,0) -> OSP ready
H13: AUH3270 | I13: =VLOOKUP(H13,Sheet2!$A:$F,6,0) -> Not 2024 scope | J13: =VLOOKUP(H13,Sheet2!$A:$G,7,0) -> OSP ready
H14: AAN3305 | I14: =VLOOKUP(H14,Sheet2!$A:$F,6,0) -> Not 2024 scope | J14: =VLOOKUP(H14,Sheet2!$A:$G,7,0) -> OSP ready

Sheet Sheet1
A2: AAN3376 | B2: 24.482847 | C2: 55.312434 | D2: AAN | E2: OD | F2: Not 2024 scope | G2: OSP ready | K2: Transport feedback required | L2: =VLOOKUP(A2,'consdolidated (2)'!B:N,13,0) -> existing fiber
A3: AUH3040 | B3: 24.17001 | C3: 54.64447 | D3: AUH | E3: OD | F3: Not 2024 scope | G3: Possible | H3: 432951.7 | I3: 7 months | K3: Transport feedback required | L3: =VLOOKUP(A3,'consdolidated (2)'!B:N,13,0) -> existing fiber
A4: AUH3350 | B4: 24.374456 | C4: 54.622955 | D4: AUH | E4: OD | F4: Not 2024 scope | G4: Taawun | K4: Transport feedback required | L4: =VLOOKUP(A4,'consdolidated (2)'!B:N,13,0) -> Y2024 fiber scope
A5: AUH3349 | B5: 24.38288 | C5: 54.61361 | D5: AUH | E5: OD | F5: Not 2024 scope | G5: Taawun | K5: Transport feedback required | L5: =VLOOKUP(A5,'consdolidated (2)'!B:N,13,0) -> Y2024 fiber scope
A6: AUH3353 | B6: 24.360467 | C6: 54.60076 | D6: AUH | E6: OD | F6: Not 2024 scope | G6: Taawun | K6: Transport feedback required | L6: =VLOOKUP(A6,'consdolidated (2)'!B:N,13,0) -> Y2024 fiber scope
A7: AUH3839 | B7: 24.455915 | C7: 54.325364 | D7: AUH | E7: OD | F7: Not 2024 scope | G7: Taawun | K7: Transport feedback required | L7: =VLOOKUP(A7,'consdolidated (2)'!B:N,13,0) -> Y2024 fiber scope
A8: AUH2728 | B8: 24.09762 | C8: 53.50104 | D8: WR | E8: OD | F8: Not 2024 scope | G8: Taawun | K8: Transport feedback required | L8: =VLOOKUP(A8,'consdolidated (2)'!B:N,13,0) -> Y2024 fiber scope
A9: AUH3887 | B9: 23.01076 | C9: 53.73097 | D9: WR | E9: OD | F9: Not 2024 scope | G9: Possible | H9: 366097.5 | I9: 6 months | K9: Transport feedback required | L9: =VLOOKUP(A9,'consdolidated (2)'!B:N,13,0) -> existing fiber
A10: AUH6182 | B10: 23.08757 | C10: 54.04193 | D10: WR | E10: OD | F10: Not 2024 scope | G10: Possible | H10: 200000 | I10: 5 months | K10: Transport feedback required | L10: =VLOOKUP(A10,'consdolidated (2)'!B:N,13,0) -> existing fiber
A11: AAN3620 | B11: 23.92988 | C11: 55.36166 | D11: AAN | E11: OD | F11: Not 2024 scope | G11: Possible | H11: 1288498.9 | I11: 10 months | J11: The route of this site passing at AAN3339,AAN2408 but they are not mentioned at this list | K11: Transport feedback required | L11: =VLOOKUP(A11,'consdolidated (2)'!B:N,13,0) -> MW 2024
A12: AAN3635 | B12: 24.56546 | C12: 55.76141 | D12: AAN | E12: OD | F12: Not 2024 scope | G12: Possible | H12: 200000 | I12: 5 months | K12: Transport feedback required | L12: =VLOOKUP(A12,'consdolidated (2)'!B:N,13,0) -> MW 2024
A13: AAN3544 | B13: 24.31274 | C13: 55.65119 | D13: AAN | E13: OD | F13: Not 2024 scope | G13: Possible | H13: 635241.04 | I13: 8 months | K13: Transport feedback required | L13: =VLOOKUP(A13,'consdolidated (2)'!B:N,13,0) -> MW 2024
A14: AAN3443 | B14: 24.29998 | C14: 55.71477 | D14: AAN | E14: OD | F14: Not 2024 scope | G14: Possible | H14: 200000 | I14: 5 months | K14: Transport feedback required | L14: =VLOOKUP(A14,'consdolidated (2)'!B:N,13,0) -> MW 2024
A15: AAN3119 | B15: 24.471723 | C15: 55.345157 | D15: AAN | E15: OD | F15: Not 2024 scope | G15: Possible | H15: 238000 | I15: 4 months | K15: Transport feedback required | L15: =VLOOKUP(A15,'consdolidated (2)'!B:N,13,0) -> existing fiber
A16: AAN3603 | B16: 23.624035 | C16: 55.514912 | D16: AAN | E16: OD | F16: Not 2024 scope | G16: Possible | H16: 450907.04 | I16: 7 months | J16: This site is dependent on AAN3396,AAN3230,AAN2427,AAN2200,AAN2269,AAN2421,AAN2268,AAN3258 | K16: Transport feedback required | L16: =VLOOKUP(A16,'consdolidated (2)'!B:N,13,0) -> MW 2024
A17: AAN3604 | B17: 23.60812 | C17: 55.41776 | D17: AAN | E17: OD | F17: Not 2024 scope | G17: Possible | H17: 1352195.4 | I17: 10 months | K17: Transport feedback required | L17: =VLOOKUP(A17,'consdolidated (2)'!B:N,13,0) -> MW 2024
A18: AUH3361 | B18: 24.3549 | C18: 54.59946 | D18: AUH | E18: OD | F18: Not 2024 scope | G18: Taawun | K18: Transport feedback required | L18: =VLOOKUP(A18,'consdolidated (2)'!B:N,13,0) -> Y2024 fiber scope
A19: AUH2801 | B19: 24.45957 | C19: 54.5549 | D19: AUH | E19: OD | F19: Not 2024 scope | G19: Not Possible | K19: Transport feedback required | L19: =VLOOKUP(A19,'consdolidated (2)'!B:N,13,0) -> MW 2024
A20: AUH3943 | B20: 24.36643 | C20: 54.61102 | D20: AUH | E20: OD | F20: Not 2024 scope | G20: Taawun | K20: Transport feedback required | L20: =VLOOKUP(A20,'consdolidated (2)'!B:N,13,0) -> Y2024 fiber scope
A21: AUH3463 | B21: 24.05678 | C21: 55.05474 | D21: AUH | E21: OD | F21: Not 2024 scope | G21: Possible | H21: 577201.8 | I21: 7 months | J21: The route of this site passing at AAN2394 but it is not mentioned at this list, also this site is dependent on AAN2393 which is in this list. | K21: Transport feedback required | L21: =VLOOKUP(A21,'consdolidated (2)'!B:N,13,0) -> MW 2024
A22: AUH3097 | B22: 24.568023 | C22: 54.794495 | D22: AUH | E22: OD | F22: Not 2024 scope | G22: Possible | H22: 220000 | J22: Military-site survey required | K22: Transport feedback required | L22: =VLOOKUP(A22,'consdolidated (2)'!B:N,13,0) -> MW 2024
A23: AUH3726 | B23: 24.26893 | C23: 54.67236 | D23: AUH | E23: OD | F23: Not 2024 scope | G23: Taawun | K23: Transport feedback required | L23: =VLOOKUP(A23,'consdolidated (2)'!B:N,13,0) -> Y2024 fiber scope
A24: AUH6134 | B24: 24.18824 | C24: 54.6697 | D24: AUH | E24: OD | F24: Not 2024 scope | G24: Possible | H24: 204893.76 | I24: 5 months | K24: Transport feedback required | L24: =VLOOKUP(A24,'consdolidated (2)'!B:N,13,0) -> existing fiber
A25: AUH3347 | B25: 24.382617 | C25: 54.631091 | D25: AUH | E25: OD | F25: Not 2024 scope | G25: Taawun | K25: Transport feedback required | L25: =VLOOKUP(A25,'consdolidated (2)'!B:N,13,0) -> Y2024 fiber scope
A26: AUH6571 | B26: 24.374616 | C26: 54.504382 | D26: AUH | E26: OD | F26: Not 2024 scope | G26: Possible | H26: 25000 | I26: 3 months | K26: Transport feedback required | L26: =VLOOKUP(A26,'consdolidated (2)'!B:N,13,0) -> existing fiber
A27: AUH3505 | B27: 23.977647 | C27: 53.796505 | D27: WR | E27: OD | F27: Not 2024 scope | G27: Site survey required | J27: CICPA Gate Pass is Required for Site Survey | K27: Transport feedback required | L27: =VLOOKUP(A27,'consdolidated (2)'!B:N,13,0) -> MW 2024
A28: AUH3941 | B28: 24.706274 | C28: 54.739298 | D28: AUH | E28: OD | F28: Not 2024 scope | G28: Taawun | K28: Transport feedback required | L28: =VLOOKUP(A28,'consdolidated (2)'!B:N,13,0) -> Y2024 fiber scope
A29: AAN3728 | B29: 24.30125 | C29: 55.12642 | D29: AAN | E29: OD | F29: Not 2024 scope | G29: Possible | H29: 1500000 | I29: 10 months | K29: Transport feedback required | L29: =VLOOKUP(A29,'consdolidated (2)'!B:N,13,0) -> MW 2024
A30: AUH1155 | B30: 24.616716 | C30: 54.738591 | D30: AUH | E30: OD | F30: Not 2024 scope | G30: Possible | H30: 45000 | I30: 3 months | K30: Transport feedback required | L30: =VLOOKUP(A30,'consdolidated (2)'!B:N,13,0) -> Y2024 fiber scope
A31: AUH1341 | B31: 24.228142 | C31: 54.685448 | D31: AUH | E31: OD | F31: Not 2024 scope | G31: Possible | H31: 280688 | I31: 4 months | K31: Transport feedback required | L31: =VLOOKUP(A31,'consdolidated (2)'!B:N,13,0) -> MW 2024
A32: AAN3111 | B32: 24.295812 | C32: 55.752072 | D32: AAN | E32: OD | F32: Not 2024 scope | G32: Possible | H32: 356727.1 | I32: 8 months | K32: Transport feedback required | L32: =VLOOKUP(A32,'consdolidated (2)'!B:N,13,0) -> MW 2024
A33: AAN3410 | B33: 24.172060 | C33: 55.958240 | D33: AAN | E33: OD | F33: Not 2024 scope | G33: Possible | H33: 370000 | I33: 7 months | K33: Transport feedback required | L33: =VLOOKUP(A33,'consdolidated (2)'!B:N,13,0) -> MW 2024
A34: AAN3411 | B34: 24.167057 | C34: 55.918268 | D34: AAN | E34: OD | F34: Not 2024 scope | G34: Possible | H34: 157619.88 | I34: 5 months | K34: Transport feedback required | L34: =VLOOKUP(A34,'consdolidated (2)'!B:N,13,0) -> Y2024 fiber scope
A35: AAN3632 | B35: 24.3238 | C35: 55.81175 | D35: AAN | E35: OD | F35: Not 2024 scope | G35: Possible | H35: 25000 | I35: 3 months | K35: Transport feedback required | L35: =VLOOKUP(A35,'consdolidated (2)'!B:N,13,0) -> Y2024 fiber scope
A36: AAN3736 | B36: 24.097510 | C36: 55.228250 | D36: AAN | E36: OD | F36: Not 2024 scope | G36: Possible | H36: 528416.36 | I36: 7 months | K36: Transport feedback required | L36: =VLOOKUP(A36,'consdolidated (2)'!B:N,13,0) -> MW 2024
A37: AAN3196 | B37: 24.134516 | C37: 55.845265 | D37: AAN | E37: OD | F37: Not 2024 scope | G37: Taawun | K37: Transport feedback required | L37: =VLOOKUP(A37,'consdolidated (2)'!B:N,13,0) -> Y2024 fiber scope
A38: AAN3112 | B38: 24.191437 | C38: 55.741211 | D38: AAN | E38: OD | F38: Not 2024 scope | G38: Possible | H38: 313598.88 | I38: 4 months | K38: Transport feedback required | L38: =VLOOKUP(A38,'consdolidated (2)'!B:N,13,0) -> MW 2024
A39: AAN3575 | B39: 24.199720 | C39: 55.782576 | D39: AAN | E39: OD | F39: Not 2024 scope | G39: Possible | H39: 25000 | I39: 3 months | K39: Transport feedback required | L39: =VLOOKUP(A39,'consdolidated (2)'!B:N,13,0) -> Y2024 fiber scope
A40: AUH1717 | B40: 24.434034 | C40: 54.625235 | D40: AUH | E40: OD | F40: Not 2024 scope | G40: Possible | H40: 50000 | I40: 5 months | K40: Transport feedback required | L40: =VLOOKUP(A40,'consdolidated (2)'!B:N,13,0) -> existing fiber
A41: AAN3199 | B41: 24.115846 | C41: 55.838763 | D41: AAN | E41: OD | F41: Not 2024 scope | G41: Taawun | K41: Transport feedback required | L41: =VLOOKUP(A41,'consdolidated (2)'!B:N,13,0) -> Y2024 fiber scope
...

Sheet OD
B1: =SUBTOTAL(3,B3:B1048576) -> 164 | C1: =SUBTOTAL(3,C3:C1048576) -> 164 | D1: =SUBTOTAL(3,D3:D1048576) -> 164 | E1: =SUBTOTAL(3,E3:E1048576) -> 164 | F1: =SUBTOTAL(3,F3:F1048576) -> 164
B2: Sitecode | C2: Region | D2: Latitude | E2: Longitude | F2: Site Type | G2: Scope | H2: Status | I2: Cost | J2: Depandancy | K2: Transport Feedback
B3: AAG6105 | C3: AAN | D3: 24.301 | E3: 55.12645 | F3: Existing | G3: OD | H3: Possible | I3: 1168587 | K3: to be via MW
B4: AAN2200 | C4: AAN | D4: 23.630973 | E4: 55.561021 | F4: Existing | G4: OD | H4: Possible | I4: 465948.03 | J4: Depend to Connect AAN2269 | K4: to be via MW
B5: AAN2263 | C5: AAN | D5: 24.10437 | E5: 55.7408 | F5: Existing | G5: OD | H5: Possible | I5: 412056.04 | K5: to be via MW
B6: AAN2268 | C6: AAN | D6: 23.7534 | E6: 55.52595 | F6: Existing | G6: OD | H6: Possible | I6: 1041620.8 | J6: Depend to Connect AAN3258 | K6: to be via MW
B7: AAN2269 | C7: AAN | D7: 23.63854 | E7: 55.56595 | F7: Existing | G7: OD | H7: Possible | I7: 1227183.1 | J7: Depend to Connect AAN2421 | K7: to be via MW
B8: AAN2270 | C8: AAN | D8: 23.5403 | E8: 55.4962 | F8: Existing | G8: OD | H8: Possible | I8: 1123293.8 | J8: Depend to Connect AAN2423 | K8: to be via MW
B9: AAN2271 | C9: AAN | D9: 23.39905 | E9: 55.42307 | F9: Existing | G9: OD | H9: Possible | I9: 381278.82 | J9: Depend to Connect AAN2424 | K9: to be via MW
B10: AAN2272 | C10: AAN | D10: 23.3157 | E10: 55.35715 | F10: Existing | G10: OD | H10: Possible | I10: 1410819.3 | J10: Depend to Connect AAN2425 | K10: to be via MW
B11: AAN2273 | C11: AAN | D11: 23.47247 | E11: 55.29668 | F11: Existing | G11: OD | H11: Possible | I11: 1490477.4 | J11: Depend to Connect AAN2383 | K11: to be via MW
B12: AAN2312 | C12: AAN | D12: 24.1454 | E12: 55.5525 | F12: Existing | G12: OD | H12: Possible | I12: 232515.62 | J12: Depend to Connect AAN3276 | K12: to be via MW
B13: AAN2314 | C13: AAN | D13: 24.17765 | E13: 55.46786 | F13: Existing | G13: OD | H13: Possible | I13: 581935.88 | K13: to be via MW
B14: AAN2326 | C14: AAN | D14: 24.12057 | E14: 55.40578 | F14: Existing | G14: OD | H14: Possible | I14: 710997.5 | J14: Depend to Connect AAN2588 | K14: to be via MW
B15: AAN2383 | C15: AAN | D15: 23.4285 | E15: 55.41047 | F15: Existing | G15: OD | H15: Possible | I15: 1027449.9 | J15: Depend to Connect AAN3287 | K15: to be via MW
B16: AAN2393 | C16: AAN | D16: 24.09338 | E16: 55.10098 | F16: Existing | G16: OD | H16: Possible | I16: 756039.55 | K16: to be via MW
B17: AAN2394 | C17: AAN | D17: 24.03036 | E17: 55.10789 | F17: Existing | G17: OD | H17: Possible | I17: 1077294.8 | J17: Depend to Connect AAN2393 | K17: to be via MW
B18: AAN2396 | C18: AAN | D18: 23.98252 | E18: 55.18256 | F18: Existing | G18: OD | H18: Possible | I18: 490163.46 | J18: Depend to Connect AAN3323 | K18: to be via MW
B19: AAN2398 | C19: AAN | D19: 24.00613 | E19: 55.40816 | F19: Existing | G19: OD | H19: Site survey required | K19: to be via MW
B20: AAN2408 | C20: AAN | D20: 23.88059 | E20: 55.40385 | F20: Existing | G20: OD | H20: Possible | I20: 974941.48 | K20: to be via MW
B21: AAN2421 | C21: AAN | D21: 23.70635 | E21: 55.56817 | F21: Existing | G21: OD | H21: Possible | I21: 1377790.5 | J21: Depend to Connect AAN2268 | K21: to be via MW
B22: AAN2422 | C22: AAN | D22: 23.642853 | E22: 55.533472 | F22: Existing | G22: OD | H22: Possible | I22: 328536.26 | J22: Depend to Connect AAN3396 | K22: to be via MW
B23: AAN2423 | C23: AAN | D23: 23.58869 | E23: 55.5346 | F23: Existing | G23: OD | H23: Possible | I23: 854510.37 | J23: Depend to Connect AAN2200 | K23: to be via MW
B24: AAN2424 | C24: AAN | D24: 23.418382 | E24: 55.422881 | F24: Existing | G24: OD | H24: Possible | I24: 411812.24 | J24: Depend to Connect AAN2424 | K24: to be via MW
B25: AAN2425 | C25: AAN | D25: 23.39908 | E25: 55.40094 | F25: Existing | G25: OD | H25: Possible | I25: 381654.18 | J25: Depend to Connect AAN3231 | K25: to be via MW
B26: AAN2426 | C26: AAN | D26: 23.48755 | E26: 55.45717 | F26: Existing | G26: OD | H26: Possible | I26: 1136245.7 | J26: Depend to Connect AAN2270 | K26: to be via MW
B27: AAN2427 | C27: AAN | D27: 23.63231 | E27: 55.55429 | F27: Existing | G27: OD | H27: Possible | I27: 208440.37 | J27: Depend to Connect AAN2200 | K27: to be via MW
B28: AAN2429 | C28: AAN | D28: 24.03254 | E28: 55.65231 | F28: Existing | G28: OD | H28: Possible | I28: 632676.75 | J28: Depend to Connect AAN3113 | K28: to be via MW
B29: AAN2436 | C29: AAN | D29: 24.21267 | E29: 55.95383 | F29: Existing | G29: OD | H29: Possible | I29: 611344.25 | K29: to be via MW
B30: AAN2472 | C30: AAN | D30: 24.13992 | E30: 55.47881 | F30: Existing | G30: OD | H30: Possible | I30: 808895.4 | J30: Depend to Connect AAN3280 | K30: to be via MW
B31: AAN2486 | C31: AAN | D31: 24.43684 | E31: 55.19456 | F31: Existing | G31: OD | H31: Possible | I31: 999138.63 | K31: to be via MW
B32: AAN2490 | C32: AAN | D32: 24.5756 | E32: 55.34289 | F32: Existing | G32: OD | H32: Possible | I32: 1418931.8 | K32: to be via MW
B33: AAN2504 | C33: AAN | D33: 23.58395 | E33: 55.45076 | F33: Existing | G33: OD | H33: Possible | I33: 1101991.8 | J33: Depend to Connect AAN2270 | K33: to be via MW
B34: AAN2511 | C34: AAN | D34: 23.986718 | E34: 55.257541 | F34: Existing | G34: OD | H34: Possible | I34: 1585477.6 | J34: Depend to Connect AAN3318 | K34: to be via MW
B35: AAN2513 | C35: AAN | D35: 24.59606 | E35: 55.39521 | F35: Existing | G35: OD | H35: Not possible | I35: 0 | K35: to be via MW
B36: AAN2530 | C36: AAN | D36: 24.08954 | E36: 55.98216 | F36: Existing | G36: OD | H36: Possible | I36: 696735.2 | K36: to be via MW
B37: AAN2815 | C37: AAN | D37: 24.2627 | E37: 55.76814 | F37: Existing | G37: OD | H37: Possible | I37: 100711.25 | K37: Y2024 fiber scope
B38: AAN2849 | C38: AAN | D38: 23.41377 | E38: 55.40641 | F38: Existing | G38: OD | H38: Possible | I38: 265715.09 | J38: Depend to Connect AAN2383 | K38: to be via MW
B39: AAN2871 | C39: AAN | D39: 24.17726 | E39: 55.73803 | F39: Existing | G39: OD | H39: Possible | I39: 316791.19 | K39: to be via MW
B40: AAN2873 | C40: AAN | D40: 24.608564 | E40: 55.461224 | F40: Existing | G40: OD | H40: Possible | I40: 732147.15 | J40: Depend to Connect AAN3134 | K40: to be via MW
...

Sheet IBS 
A1: Project Code | B1: Sitecode | C1: Region | D1: Latitude | E1: Longitude | F1: Site Type | G1: Scope | H1: Status | I1: Cost | J1: Transport Feedback
B2: IAD5904 | C2: AUH | D2: 24.5205 | E2: 54.4369 | F2: Existing | G2: ibs | H2: Possible | I2: 67357.778 | J2: Y2024 fiber scope
B3: AUH0537 | C3: AUH | D3: 24.433748 | E3: 54.439708 | F3: Existing | G3: ibs | H3: Possible | I3: 53949.727 | J3: Y2024 fiber scope
B4: AUH0553 | C4: AUH | D4: 24.483731 | E4: 54.37823 | F4: Existing | G4: ibs | H4: Possible | I4: 42864 | J4: Y2024 fiber scope
B5: AUH0917 | C5: AUH | D5: 24.424904 | E5: 54.650516 | F5: Existing | G5: ibs | H5: Possible | I5: 196967.85 | J5: to be via MW
B6: AUH0860 | C6: AUH | D6: 24.497805 | E6: 54.368348 | F6: Existing | G6: ibs | H6: Possible | I6: 202297.7 | J6: to be via MW
B7: AUH0981 | C7: AUH | D7: 24.435233 | E7: 54.418416 | F7: Existing | G7: ibs | H7: Possible | I7: 28800 | J7: Y2024 fiber scope
B8: AUH0676 | C8: AUH | D8: 24.0896 | E8: 52.64443 | F8: Existing | G8: ibs | H8: Possible | I8: 54450 | J8: Y2024 fiber scope
B9: AAN0014 | C9: AUH | D9: 24.230733 | E9: 55.733449 | F9: Existing | G9: ibs | H9: POSSIBLE | I9: 116261.73 | J9: to be via MW
B10: AAN0003 | C10: AUH | D10: 24.258603 | E10: 55.616435 | F10: Existing | G10: ibs | H10: Possible | I10: 30600 | J10: Y2024 fiber scope
B11: AAN0005 | C11: AUH | D11: 24.23862 | E11: 55.73709 | F11: Existing | G11: ibs | H11: Possible | I11: 135595.2 | J11: to be via MW
B12: AUH0927 | C12: AUH | D12: 24.417964 | E12: 54.440138 | F12: Existing | G12: ibs | H12: Possible | I12: 62317.328 | J12: Y2024 fiber scope
B13: DXB0371 | C13: AUH | D13: 25.282984 | E13: 55.317734 | F13: Existing | G13: ibs | H13: OSP Provisioned | I13: 30000 | J13: Y2024 fiber scope
... B16: RAK0527 | C16: AUH | D16: 25.685279 | E16: 55.773331 | F16: Existing | G16: ibs | H16: NE Region | I16: 0 | J16: NE Region
B17: AUH0789 | C17: AUH | D17: 24.49847 | E17: 54.39054 | F17: Existing | G17: ibs | H17: PIS with ETC | I17: 0 | J17: to be via MW
B18: AUH0575 | C18: AUH | D18: 24.503046 | E18: 54.370584 | F18: Existing | G18: ibs | H18: Possible | I18: 40808.202 | J18: Y2024 fiber scope
B19: AUH0890 | C19: AUH | D19: 24.326344 | E19: 54.616009 | F19: Existing | G19: ibs | H19: Possible | I19: 30000 | J19: Y2024 fiber scope
B20: AUH0417 | C20: AUH | D20: 24.492308 | E20: 54.36734 | F20: Existing | G20: ibs | H20: Possible | I20: 39214.302 | J20: Y2024 fiber scope
B21: AUH0691 | C21: AUH | D21: 24.38906 | E21: 54.22176 | F21: Existing | G21: ibs | H21: Not Possible | I21: 0 | J21: to be via MW
B22: AUH0419 | C22: AUH | D22: 24.43846 | E22: 54.572373 | F22: Existing | G22: ibs | H22: Possible | I22: 57614.076 | J22: Y2024 fiber scope
B23: AUH0745 | C23: AUH | D23: 24.439077 | E23: 54.571198 | F23: Existing | G23: ibs | H23: Possible | I23: 30000 | J23: Y2024 fiber scope
B24: AUH0420 | C24: AUH | D24: 24.438783 | E24: 54.574251 | F24: Existing | G24: ibs | H24: Possible | I24: 216467.88 | J24: to be via MW
B25: AUH0418 | C25: AUH | D25: 24.572776 | E25: 54.694301 | F25: Existing | G25: ibs | H25: Possible | I25: 30000 | J25: Y2024 fiber scope
B26: AUH0862 | C26: AUH | D26: 24.499492 | E26: 54.370806 | F26: Existing | G26: ibs | H26: POSSIBLE | I26: 152591.04 | J26: to be via MW
B27: AUH0481 | C27: AUH | D27: 24.495098 | E27: 54.374017 | F27: Existing | G27: ibs | H27: Possible | I27: 30000 | J27: Y2024 fiber scope
B28: AUH0405 | C28: AUH | D28: 24.453072° | E28: 54.398531° | F28: Existing | G28: ibs | H28: Possible | I28: 83659.913 | J28: Y2024 fiber scope
B29: AUH0923 | C29: AUH | D29: 24.500071 | E29: 54.371225 | F29: Existing | G29: ibs | H29: Possible | I29: 131049.42 | J29: to be via MW
B30: AAN0027 | C30: AUH | D30: 23.637272 | E30: 55.56563 | F30: Existing | G30: ibs | H30: Possible | I30: 4197157.9 | J30: to be via MW
B31: AUH0527 | C31: AUH | D31: 24.471166 | E31: 54.373715 | F31: Existing | G31: ibs | H31: Possible | I31: 58509.266 | J31: Y2024 fiber scope
B32: AUH0529 | C32: AUH | D32: 24.471312 | E32: 54.37451 | F32: Existing | G32: ibs | H32: Possible | I32: 30000 | J32: Y2024 fiber scope
B33: AUH0528 | C33: AUH | D33: 24.471846 | E33: 54.373934 | F33: Existing | G33: ibs | H33: Possible | I33: 60987.337 | J33: Y2024 fiber scope
B34: AUH5673B | C34: AUH | D34: 24.429202 | E34: 54.640822 | F34: Existing | G34: ibs | H34: Possible | I34: 248391.82 | J34: to be via MW
B35: AUH5532C | C35: AUH | D35: 24.456996 | E35: 54.634034 | F35: Existing | G35: ibs | H35: Possible | I35: 316874.7 | J35: to be via MW
B36: AAN5399D | C36: AUH | D36: 24.5761 | E36: 55.747362 | F36: Existing | G36: ibs | H36: Possible | I36: 112411.74 | J36: to be via MW
B37: AUH5532A | C37: AUH | D37: 24.366026 | E37: 54.192731 | F37: Existing | G37: ibs | H37: Not Possible | I37: 0 | J37: to be via MW
B38: AUH5403D | C38: AUH | D38: 24.277247 | E38: 52.609527 | F38: Existing | G38: ibs | H38: Not Possible | I38: 0 | J38: to be via MW
B39: AAN5399B | C39: AUH | D39: 24.593855 | E39: 55.746089 | F39: Existing | G39: ibs | H39: OSP Provisioned | I39: 30000 | J39: Y2024 fiber scope
B40: AUH5560A | C40: AUH | D40: 24.778891° | E40: 54.737421° | F40: Existing | G40: ibs | H40: Possible | I40: 30000 | J40: Y2024 fiber scope
B41: AUH5560B | C41: AUH | D41: 24.778337 | E41: 54.737494 | F41: Existing | G41: ibs | H41: Possible | I41: 30000 | J41: Y2024 fiber scope
B42: AUH5818F | C42: AUH | D42: 24.252515 | E42: 54.555066 | F42: Existing | G42: ibs | H42: Possible | I42: 258032.7 | J42: to be via MW
...
